Workbook

Sheet 算工作數
A1: 不算入六日，加班時數只算到19:30
A3: 員工 | B3: 每月 | C3: 工作天數 | D3: 工作總時數 | Z3: 員工來源(隱藏)
A4: =IF(Z4="","",IF(ISNUMBER(SEARCH("員工代號:",Z4)),"員工代號:","")&LEFT(LEFT(TRIM(SUBSTITUTE(Z4,"員工代號:","")),FIND(" ",TRIM(SUBSTITUTE(Z4,"員工代號:","")))-1),2)&REPT("*",MAX(1,LEN(LEFT(TRIM(SUBSTITUTE(Z4,"員工代號:","")),FIND(" ",TRIM(SUBSTITUTE(Z4,"員工代號:","")))-1))-4))&RIGHT(LEFT(TRIM(SUBSTITUTE(Z4,"員工代號:","")),FIND(" ",TRIM(SUBSTITUTE(Z4,"員工代號:","")))-1),2)&" "&IF(LEN(MID(TRIM(SUBSTITUTE(Z4,"員工代號:","")),FIND(" ",TRIM(SUBSTITUTE(Z4,"員工代號:","")))+1,255))<=1,"*",IF(LEN(MID(TRIM(SUBSTITUTE(Z4,"員工代號:","")),FIND(" ",TRIM(SUBSTITUTE(Z4,"員工代號:","")))+1,255))=2,LEFT(MID(TRIM(SUBSTITUTE(Z4,"員工代號:","")),FIND(" ",TRIM(SUBSTITUTE(Z4,"員工代號:","")))+1,255),1)&"*",LEFT(MID(TRIM(SUBSTITUTE(Z4,"員工代號:","")),FIND(" ",TRIM(SUBSTITUTE(Z4,"員工代號:","")))+1,255),1)&REPT("*",LEN(MID(TRIM(SUBSTITUTE(Z4,"員工代號:","")),FIND(" ",TRIM(SUBSTITUTE(Z4,"員工代號:","")))+1,255))-2)&RIGHT(MID(TRIM(SUBSTITUTE(Z4,"員工代號:","")),FIND(" ",TRIM(SUBSTITUTE(Z4,"員工代號:","")))+1,255),1)))) | B4: 2026-06 | C4: =COUNTIFS(計算明細!$B:$B,$A4,計算明細!$L:$L,$B4,計算明細!$K:$K,1) | D4: =TEXT(SUMIFS(計算明細!$J:$J,計算明細!$B:$B,$A4,計算明細!$L:$L,$B4),"[h]:mm") | Z4: 員工代號:97668 郭靖
A5: =IF(Z5="","",IF(ISNUMBER(SEARCH("員工代號:",Z5)),"員工代號:","")&LEFT(LEFT(TRIM(SUBSTITUTE(Z5,"員工代號:","")),FIND(" ",TRIM(SUBSTITUTE(Z5,"員工代號:","")))-1),2)&REPT("*",MAX(1,LEN(LEFT(TRIM(SUBSTITUTE(Z5,"員工代號:","")),FIND(" ",TRIM(SUBSTITUTE(Z5,"員工代號:","")))-1))-4))&RIGHT(LEFT(TRIM(SUBSTITUTE(Z5,"員工代號:","")),FIND(" ",TRIM(SUBSTITUTE(Z5,"員工代號:","")))-1),2)&" "&IF(LEN(MID(TRIM(SUBSTITUTE(Z5,"員工代號:","")),FIND(" ",TRIM(SUBSTITUTE(Z5,"員工代號:","")))+1,255))<=1,"*",IF(LEN(MID(TRIM(SUBSTITUTE(Z5,"員工代號:","")),FIND(" ",TRIM(SUBSTITUTE(Z5,"員工代號:","")))+1,255))=2,LEFT(MID(TRIM(SUBSTITUTE(Z5,"員工代號:","")),FIND(" ",TRIM(SUBSTITUTE(Z5,"員工代號:","")))+1,255),1)&"*",LEFT(MID(TRIM(SUBSTITUTE(Z5,"員工代號:","")),FIND(" ",TRIM(SUBSTITUTE(Z5,"員工代號:","")))+1,255),1)&REPT("*",LEN(MID(TRIM(SUBSTITUTE(Z5,"員工代號:","")),FIND(" ",TRIM(SUBSTITUTE(Z5,"員工代號:","")))+1,255))-2)&RIGHT(MID(TRIM(SUBSTITUTE(Z5,"員工代號:","")),FIND(" ",TRIM(SUBSTITUTE(Z5,"員工代號:","")))+1,255),1)))) | B5: 2026-06 | C5: =COUNTIFS(計算明細!$B:$B,$A5,計算明細!$L:$L,$B5,計算明細!$K:$K,1) | D5: =TEXT(SUMIFS(計算明細!$J:$J,計算明細!$B:$B,$A5,計算明細!$L:$L,$B5),"[h]:mm") | Z5: 員工代號:85479 黃蓉
A6: =IF(Z6="","",IF(ISNUMBER(SEARCH("員工代號:",Z6)),"員工代號:","")&LEFT(LEFT(TRIM(SUBSTITUTE(Z6,"員工代號:","")),FIND(" ",TRIM(SUBSTITUTE(Z6,"員工代號:","")))-1),2)&REPT("*",MAX(1,LEN(LEFT(TRIM(SUBSTITUTE(Z6,"員工代號:","")),FIND(" ",TRIM(SUBSTITUTE(Z6,"員工代號:","")))-1))-4))&RIGHT(LEFT(TRIM(SUBSTITUTE(Z6,"員工代號:","")),FIND(" ",TRIM(SUBSTITUTE(Z6,"員工代號:","")))-1),2)&" "&IF(LEN(MID(TRIM(SUBSTITUTE(Z6,"員工代號:","")),FIND(" ",TRIM(SUBSTITUTE(Z6,"員工代號:","")))+1,255))<=1,"*",IF(LEN(MID(TRIM(SUBSTITUTE(Z6,"員工代號:","")),FIND(" ",TRIM(SUBSTITUTE(Z6,"員工代號:","")))+1,255))=2,LEFT(MID(TRIM(SUBSTITUTE(Z6,"員工代號:","")),FIND(" ",TRIM(SUBSTITUTE(Z6,"員工代號:","")))+1,255),1)&"*",LEFT(MID(TRIM(SUBSTITUTE(Z6,"員工代號:","")),FIND(" ",TRIM(SUBSTITUTE(Z6,"員工代號:","")))+1,255),1)&REPT("*",LEN(MID(TRIM(SUBSTITUTE(Z6,"員工代號:","")),FIND(" ",TRIM(SUBSTITUTE(Z6,"員工代號:","")))+1,255))-2)&RIGHT(MID(TRIM(SUBSTITUTE(Z6,"員工代號:","")),FIND(" ",TRIM(SUBSTITUTE(Z6,"員工代號:","")))+1,255),1)))) | B6: 2026-06 | C6: =COUNTIFS(計算明細!$B:$B,$A6,計算明細!$L:$L,$B6,計算明細!$K:$K,1) | D6: =TEXT(SUMIFS(計算明細!$J:$J,計算明細!$B:$B,$A6,計算明細!$L:$L,$B6),"[h]:mm") | Z6: 員工代號:96638 楊過
A7: =IF(Z7="","",IF(ISNUMBER(SEARCH("員工代號:",Z7)),"員工代號:","")&LEFT(LEFT(TRIM(SUBSTITUTE(Z7,"員工代號:","")),FIND(" ",TRIM(SUBSTITUTE(Z7,"員工代號:","")))-1),2)&REPT("*",MAX(1,LEN(LEFT(TRIM(SUBSTITUTE(Z7,"員工代號:","")),FIND(" ",TRIM(SUBSTITUTE(Z7,"員工代號:","")))-1))-4))&RIGHT(LEFT(TRIM(SUBSTITUTE(Z7,"員工代號:","")),FIND(" ",TRIM(SUBSTITUTE(Z7,"員工代號:","")))-1),2)&" "&IF(LEN(MID(TRIM(SUBSTITUTE(Z7,"員工代號:","")),FIND(" ",TRIM(SUBSTITUTE(Z7,"員工代號:","")))+1,255))<=1,"*",IF(LEN(MID(TRIM(SUBSTITUTE(Z7,"員工代號:","")),FIND(" ",TRIM(SUBSTITUTE(Z7,"員工代號:","")))+1,255))=2,LEFT(MID(TRIM(SUBSTITUTE(Z7,"員工代號:","")),FIND(" ",TRIM(SUBSTITUTE(Z7,"員工代號:","")))+1,255),1)&"*",LEFT(MID(TRIM(SUBSTITUTE(Z7,"員工代號:","")),FIND(" ",TRIM(SUBSTITUTE(Z7,"員工代號:","")))+1,255),1)&REPT("*",LEN(MID(TRIM(SUBSTITUTE(Z7,"員工代號:","")),FIND(" ",TRIM(SUBSTITUTE(Z7,"員工代號:","")))+1,255))-2)&RIGHT(MID(TRIM(SUBSTITUTE(Z7,"員工代號:","")),FIND(" ",TRIM(SUBSTITUTE(Z7,"員工代號:","")))+1,255),1)))) | B7: 2026-06 | C7: =COUNTIFS(計算明細!$B:$B,$A7,計算明細!$L:$L,$B7,計算明細!$K:$K,1) | D7: =TEXT(SUMIFS(計算明細!$J:$J,計算明細!$B:$B,$A7,計算明細!$L:$L,$B7),"[h]:mm") | Z7: 員工代號:87942 小龍女
A8: =IF(Z8="","",IF(ISNUMBER(SEARCH("員工代號:",Z8)),"員工代號:","")&LEFT(LEFT(TRIM(SUBSTITUTE(Z8,"員工代號:","")),FIND(" ",TRIM(SUBSTITUTE(Z8,"員工代號:","")))-1),2)&REPT("*",MAX(1,LEN(LEFT(TRIM(SUBSTITUTE(Z8,"員工代號:","")),FIND(" ",TRIM(SUBSTITUTE(Z8,"員工代號:","")))-1))-4))&RIGHT(LEFT(TRIM(SUBSTITUTE(Z8,"員工代號:","")),FIND(" ",TRIM(SUBSTITUTE(Z8,"員工代號:","")))-1),2)&" "&IF(LEN(MID(TRIM(SUBSTITUTE(Z8,"員工代號:","")),FIND(" ",TRIM(SUBSTITUTE(Z8,"員工代號:","")))+1,255))<=1,"*",IF(LEN(MID(TRIM(SUBSTITUTE(Z8,"員工代號:","")),FIND(" ",TRIM(SUBSTITUTE(Z8,"員工代號:","")))+1,255))=2,LEFT(MID(TRIM(SUBSTITUTE(Z8,"員工代號:","")),FIND(" ",TRIM(SUBSTITUTE(Z8,"員工代號:","")))+1,255),1)&"*",LEFT(MID(TRIM(SUBSTITUTE(Z8,"員工代號:","")),FIND(" ",TRIM(SUBSTITUTE(Z8,"員工代號:","")))+1,255),1)&REPT("*",LEN(MID(TRIM(SUBSTITUTE(Z8,"員工代號:","")),FIND(" ",TRIM(SUBSTITUTE(Z8,"員工代號:","")))+1,255))-2)&RIGHT(MID(TRIM(SUBSTITUTE(Z8,"員工代號:","")),FIND(" ",TRIM(SUBSTITUTE(Z8,"員工代號:","")))+1,255),1)))) | B8: 2026-06 | C8: =COUNTIFS(計算明細!$B:$B,$A8,計算明細!$L:$L,$B8,計算明細!$K:$K,1) | D8: =TEXT(SUMIFS(計算明細!$J:$J,計算明細!$B:$B,$A8,計算明細!$L:$L,$B8),"[h]:mm") | Z8: 員工代號:84799 張無忌
A9: =IF(Z9="","",IF(ISNUMBER(SEARCH("員工代號:",Z9)),"員工代號:","")&LEFT(LEFT(TRIM(SUBSTITUTE(Z9,"員工代號:","")),FIND(" ",TRIM(SUBSTITUTE(Z9,"員工代號:","")))-1),2)&REPT("*",MAX(1,LEN(LEFT(TRIM(SUBSTITUTE(Z9,"員工代號:","")),FIND(" ",TRIM(SUBSTITUTE(Z9,"員工代號:","")))-1))-4))&RIGHT(LEFT(TRIM(SUBSTITUTE(Z9,"員工代號:","")),FIND(" ",TRIM(SUBSTITUTE(Z9,"員工代號:","")))-1),2)&" "&IF(LEN(MID(TRIM(SUBSTITUTE(Z9,"員工代號:","")),FIND(" ",TRIM(SUBSTITUTE(Z9,"員工代號:","")))+1,255))<=1,"*",IF(LEN(MID(TRIM(SUBSTITUTE(Z9,"員工代號:","")),FIND(" ",TRIM(SUBSTITUTE(Z9,"員工代號:","")))+1,255))=2,LEFT(MID(TRIM(SUBSTITUTE(Z9,"員工代號:","")),FIND(" ",TRIM(SUBSTITUTE(Z9,"員工代號:","")))+1,255),1)&"*",LEFT(MID(TRIM(SUBSTITUTE(Z9,"員工代號:","")),FIND(" ",TRIM(SUBSTITUTE(Z9,"員工代號:","")))+1,255),1)&REPT("*",LEN(MID(TRIM(SUBSTITUTE(Z9,"員工代號:","")),FIND(" ",TRIM(SUBSTITUTE(Z9,"員工代號:","")))+1,255))-2)&RIGHT(MID(TRIM(SUBSTITUTE(Z9,"員工代號:","")),FIND(" ",TRIM(SUBSTITUTE(Z9,"員工代號:","")))+1,255),1)))) | B9: 2026-06 | C9: =COUNTIFS(計算明細!$B:$B,$A9,計算明細!$L:$L,$B9,計算明細!$K:$K,1) | D9: =TEXT(SUMIFS(計算明細!$J:$J,計算明細!$B:$B,$A9,計算明細!$L:$L,$B9),"[h]:mm") | Z9: 員工代號:95606 趙敏
A10: =IF(Z10="","",IF(ISNUMBER(SEARCH("員工代號:",Z10)),"員工代號:","")&LEFT(LEFT(TRIM(SUBSTITUTE(Z10,"員工代號:","")),FIND(" ",TRIM(SUBSTITUTE(Z10,"員工代號:","")))-1),2)&REPT("*",MAX(1,LEN(LEFT(TRIM(SUBSTITUTE(Z10,"員工代號:","")),FIND(" ",TRIM(SUBSTITUTE(Z10,"員工代號:","")))-1))-4))&RIGHT(LEFT(TRIM(SUBSTITUTE(Z10,"員工代號:","")),FIND(" ",TRIM(SUBSTITUTE(Z10,"員工代號:","")))-1),2)&" "&IF(LEN(MID(TRIM(SUBSTITUTE(Z10,"員工代號:","")),FIND(" ",TRIM(SUBSTITUTE(Z10,"員工代號:","")))+1,255))<=1,"*",IF(LEN(MID(TRIM(SUBSTITUTE(Z10,"員工代號:","")),FIND(" ",TRIM(SUBSTITUTE(Z10,"員工代號:","")))+1,255))=2,LEFT(MID(TRIM(SUBSTITUTE(Z10,"員工代號:","")),FIND(" ",TRIM(SUBSTITUTE(Z10,"員工代號:","")))+1,255),1)&"*",LEFT(MID(TRIM(SUBSTITUTE(Z10,"員工代號:","")),FIND(" ",TRIM(SUBSTITUTE(Z10,"員工代號:","")))+1,255),1)&REPT("*",LEN(MID(TRIM(SUBSTITUTE(Z10,"員工代號:","")),FIND(" ",TRIM(SUBSTITUTE(Z10,"員工代號:","")))+1,255))-2)&RIGHT(MID(TRIM(SUBSTITUTE(Z10,"員工代號:","")),FIND(" ",TRIM(SUBSTITUTE(Z10,"員工代號:","")))+1,255),1)))) | B10: 2026-06 | C10: =COUNTIFS(計算明細!$B:$B,$A10,計算明細!$L:$L,$B10,計算明細!$K:$K,1) | D10: =TEXT(SUMIFS(計算明細!$J:$J,計算明細!$B:$B,$A10,計算明細!$L:$L,$B10),"[h]:mm") | Z10: 員工代號:93704 令狐沖
A11: =IF(Z11="","",IF(ISNUMBER(SEARCH("員工代號:",Z11)),"員工代號:","")&LEFT(LEFT(TRIM(SUBSTITUTE(Z11,"員工代號:","")),FIND(" ",TRIM(SUBSTITUTE(Z11,"員工代號:","")))-1),2)&REPT("*",MAX(1,LEN(LEFT(TRIM(SUBSTITUTE(Z11,"員工代號:","")),FIND(" ",TRIM(SUBSTITUTE(Z11,"員工代號:","")))-1))-4))&RIGHT(LEFT(TRIM(SUBSTITUTE(Z11,"員工代號:","")),FIND(" ",TRIM(SUBSTITUTE(Z11,"員工代號:","")))-1),2)&" "&IF(LEN(MID(TRIM(SUBSTITUTE(Z11,"員工代號:","")),FIND(" ",TRIM(SUBSTITUTE(Z11,"員工代號:","")))+1,255))<=1,"*",IF(LEN(MID(TRIM(SUBSTITUTE(Z11,"員工代號:","")),FIND(" ",TRIM(SUBSTITUTE(Z11,"員工代號:","")))+1,255))=2,LEFT(MID(TRIM(SUBSTITUTE(Z11,"員工代號:","")),FIND(" ",TRIM(SUBSTITUTE(Z11,"員工代號:","")))+1,255),1)&"*",LEFT(MID(TRIM(SUBSTITUTE(Z11,"員工代號:","")),FIND(" ",TRIM(SUBSTITUTE(Z11,"員工代號:","")))+1,255),1)&REPT("*",LEN(MID(TRIM(SUBSTITUTE(Z11,"員工代號:","")),FIND(" ",TRIM(SUBSTITUTE(Z11,"員工代號:","")))+1,255))-2)&RIGHT(MID(TRIM(SUBSTITUTE(Z11,"員工代號:","")),FIND(" ",TRIM(SUBSTITUTE(Z11,"員工代號:","")))+1,255),1)))) | B11: 2026-06 | C11: =COUNTIFS(計算明細!$B:$B,$A11,計算明細!$L:$L,$B11,計算明細!$K:$K,1) | D11: =TEXT(SUMIFS(計算明細!$J:$J,計算明細!$B:$B,$A11,計算明細!$L:$L,$B11),"[h]:mm") | Z11: 員工代號:94889 任盈盈
A12: =IF(Z12="","",IF(ISNUMBER(SEARCH("員工代號:",Z12)),"員工代號:","")&LEFT(LEFT(TRIM(SUBSTITUTE(Z12,"員工代號:","")),FIND(" ",TRIM(SUBSTITUTE(Z12,"員工代號:","")))-1),2)&REPT("*",MAX(1,LEN(LEFT(TRIM(SUBSTITUTE(Z12,"員工代號:","")),FIND(" ",TRIM(SUBSTITUTE(Z12,"員工代號:","")))-1))-4))&RIGHT(LEFT(TRIM(SUBSTITUTE(Z12,"員工代號:","")),FIND(" ",TRIM(SUBSTITUTE(Z12,"員工代號:","")))-1),2)&" "&IF(LEN(MID(TRIM(SUBSTITUTE(Z12,"員工代號:","")),FIND(" ",TRIM(SUBSTITUTE(Z12,"員工代號:","")))+1,255))<=1,"*",IF(LEN(MID(TRIM(SUBSTITUTE(Z12,"員工代號:","")),FIND(" ",TRIM(SUBSTITUTE(Z12,"員工代號:","")))+1,255))=2,LEFT(MID(TRIM(SUBSTITUTE(Z12,"員工代號:","")),FIND(" ",TRIM(SUBSTITUTE(Z12,"員工代號:","")))+1,255),1)&"*",LEFT(MID(TRIM(SUBSTITUTE(Z12,"員工代號:","")),FIND(" ",TRIM(SUBSTITUTE(Z12,"員工代號:","")))+1,255),1)&REPT("*",LEN(MID(TRIM(SUBSTITUTE(Z12,"員工代號:","")),FIND(" ",TRIM(SUBSTITUTE(Z12,"員工代號:","")))+1,255))-2)&RIGHT(MID(TRIM(SUBSTITUTE(Z12,"員工代號:","")),FIND(" ",TRIM(SUBSTITUTE(Z12,"員工代號:","")))+1,255),1)))) | B12: 2026-06 | C12: =COUNTIFS(計算明細!$B:$B,$A12,計算明細!$L:$L,$B12,計算明細!$K:$K,1) | D12: =TEXT(SUMIFS(計算明細!$J:$J,計算明細!$B:$B,$A12,計算明細!$L:$L,$B12),"[h]:mm") | Z12: 員工代號:81702 胡斐
A13: =IF(Z13="","",IF(ISNUMBER(SEARCH("員工代號:",Z13)),"員工代號:","")&LEFT(LEFT(TRIM(SUBSTITUTE(Z13,"員工代號:","")),FIND(" ",TRIM(SUBSTITUTE(Z13,"員工代號:","")))-1),2)&REPT("*",MAX(1,LEN(LEFT(TRIM(SUBSTITUTE(Z13,"員工代號:","")),FIND(" ",TRIM(SUBSTITUTE(Z13,"員工代號:","")))-1))-4))&RIGHT(LEFT(TRIM(SUBSTITUTE(Z13,"員工代號:","")),FIND(" ",TRIM(SUBSTITUTE(Z13,"員工代號:","")))-1),2)&" "&IF(LEN(MID(TRIM(SUBSTITUTE(Z13,"員工代號:","")),FIND(" ",TRIM(SUBSTITUTE(Z13,"員工代號:","")))+1,255))<=1,"*",IF(LEN(MID(TRIM(SUBSTITUTE(Z13,"員工代號:","")),FIND(" ",TRIM(SUBSTITUTE(Z13,"員工代號:","")))+1,255))=2,LEFT(MID(TRIM(SUBSTITUTE(Z13,"員工代號:","")),FIND(" ",TRIM(SUBSTITUTE(Z13,"員工代號:","")))+1,255),1)&"*",LEFT(MID(TRIM(SUBSTITUTE(Z13,"員工代號:","")),FIND(" ",TRIM(SUBSTITUTE(Z13,"員工代號:","")))+1,255),1)&REPT("*",LEN(MID(TRIM(SUBSTITUTE(Z13,"員工代號:","")),FIND(" ",TRIM(SUBSTITUTE(Z13,"員工代號:","")))+1,255))-2)&RIGHT(MID(TRIM(SUBSTITUTE(Z13,"員工代號:","")),FIND(" ",TRIM(SUBSTITUTE(Z13,"員工代號:","")))+1,255),1)))) | B13: 2026-06 | C13: =COUNTIFS(計算明細!$B:$B,$A13,計算明細!$L:$L,$B13,計算明細!$K:$K,1) | D13: =TEXT(SUMIFS(計算明細!$J:$J,計算明細!$B:$B,$A13,計算明細!$L:$L,$B13),"[h]:mm") | Z13: 員工代號:94827 袁紫衣
A14: =IF(Z14="","",IF(ISNUMBER(SEARCH("員工代號:",Z14)),"員工代號:","")&LEFT(LEFT(TRIM(SUBSTITUTE(Z14,"員工代號:","")),FIND(" ",TRIM(SUBSTITUTE(Z14,"員工代號:","")))-1),2)&REPT("*",MAX(1,LEN(LEFT(TRIM(SUBSTITUTE(Z14,"員工代號:","")),FIND(" ",TRIM(SUBSTITUTE(Z14,"員工代號:","")))-1))-4))&RIGHT(LEFT(TRIM(SUBSTITUTE(Z14,"員工代號:","")),FIND(" ",TRIM(SUBSTITUTE(Z14,"員工代號:","")))-1),2)&" "&IF(LEN(MID(TRIM(SUBSTITUTE(Z14,"員工代號:","")),FIND(" ",TRIM(SUBSTITUTE(Z14,"員工代號:","")))+1,255))<=1,"*",IF(LEN(MID(TRIM(SUBSTITUTE(Z14,"員工代號:","")),FIND(" ",TRIM(SUBSTITUTE(Z14,"員工代號:","")))+1,255))=2,LEFT(MID(TRIM(SUBSTITUTE(Z14,"員工代號:","")),FIND(" ",TRIM(SUBSTITUTE(Z14,"員工代號:","")))+1,255),1)&"*",LEFT(MID(TRIM(SUBSTITUTE(Z14,"員工代號:","")),FIND(" ",TRIM(SUBSTITUTE(Z14,"員工代號:","")))+1,255),1)&REPT("*",LEN(MID(TRIM(SUBSTITUTE(Z14,"員工代號:","")),FIND(" ",TRIM(SUBSTITUTE(Z14,"員工代號:","")))+1,255))-2)&RIGHT(MID(TRIM(SUBSTITUTE(Z14,"員工代號:","")),FIND(" ",TRIM(SUBSTITUTE(Z14,"員工代號:","")))+1,255),1)))) | B14: 2026-06 | C14: =COUNTIFS(計算明細!$B:$B,$A14,計算明細!$L:$L,$B14,計算明細!$K:$K,1) | D14: =TEXT(SUMIFS(計算明細!$J:$J,計算明細!$B:$B,$A14,計算明細!$L:$L,$B14),"[h]:mm") | Z14: 員工代號:87967 陳家洛
A15: =IF(Z15="","",IF(ISNUMBER(SEARCH("員工代號:",Z15)),"員工代號:","")&LEFT(LEFT(TRIM(SUBSTITUTE(Z15,"員工代號:","")),FIND(" ",TRIM(SUBSTITUTE(Z15,"員工代號:","")))-1),2)&REPT("*",MAX(1,LEN(LEFT(TRIM(SUBSTITUTE(Z15,"員工代號:","")),FIND(" ",TRIM(SUBSTITUTE(Z15,"員工代號:","")))-1))-4))&RIGHT(LEFT(TRIM(SUBSTITUTE(Z15,"員工代號:","")),FIND(" ",TRIM(SUBSTITUTE(Z15,"員工代號:","")))-1),2)&" "&IF(LEN(MID(TRIM(SUBSTITUTE(Z15,"員工代號:","")),FIND(" ",TRIM(SUBSTITUTE(Z15,"員工代號:","")))+1,255))<=1,"*",IF(LEN(MID(TRIM(SUBSTITUTE(Z15,"員工代號:","")),FIND(" ",TRIM(SUBSTITUTE(Z15,"員工代號:","")))+1,255))=2,LEFT(MID(TRIM(SUBSTITUTE(Z15,"員工代號:","")),FIND(" ",TRIM(SUBSTITUTE(Z15,"員工代號:","")))+1,255),1)&"*",LEFT(MID(TRIM(SUBSTITUTE(Z15,"員工代號:","")),FIND(" ",TRIM(SUBSTITUTE(Z15,"員工代號:","")))+1,255),1)&REPT("*",LEN(MID(TRIM(SUBSTITUTE(Z15,"員工代號:","")),FIND(" ",TRIM(SUBSTITUTE(Z15,"員工代號:","")))+1,255))-2)&RIGHT(MID(TRIM(SUBSTITUTE(Z15,"員工代號:","")),FIND(" ",TRIM(SUBSTITUTE(Z15,"員工代號:","")))+1,255),1)))) | B15: 2026-06 | C15: =COUNTIFS(計算明細!$B:$B,$A15,計算明細!$L:$L,$B15,計算明細!$K:$K,1) | D15: =TEXT(SUMIFS(計算明細!$J:$J,計算明細!$B:$B,$A15,計算明細!$L:$L,$B15),"[h]:mm") | Z15: 員工代號:96030 霍青桐
... A19: =IF(Z19="","",IF(ISNUMBER(SEARCH("員工代號:",Z19)),"員工代號:","")&LEFT(LEFT(TRIM(SUBSTITUTE(Z19,"員工代號:","")),FIND(" ",TRIM(SUBSTITUTE(Z19,"員工代號:","")))-1),2)&REPT("*",MAX(1,LEN(LEFT(TRIM(SUBSTITUTE(Z19,"員工代號:","")),FIND(" ",TRIM(SUBSTITUTE(Z19,"員工代號:","")))-1))-4))&RIGHT(LEFT(TRIM(SUBSTITUTE(Z19,"員工代號:","")),FIND(" ",TRIM(SUBSTITUTE(Z19,"員工代號:","")))-1),2)&" "&IF(LEN(MID(TRIM(SUBSTITUTE(Z19,"員工代號:","")),FIND(" ",TRIM(SUBSTITUTE(Z19,"員工代號:","")))+1,255))<=1,"*",IF(LEN(MID(TRIM(SUBSTITUTE(Z19,"員工代號:","")),FIND(" ",TRIM(SUBSTITUTE(Z19,"員工代號:","")))+1,255))=2,LEFT(MID(TRIM(SUBSTITUTE(Z19,"員工代號:","")),FIND(" ",TRIM(SUBSTITUTE(Z19,"員工代號:","")))+1,255),1)&"*",LEFT(MID(TRIM(SUBSTITUTE(Z19,"員工代號:","")),FIND(" ",TRIM(SUBSTITUTE(Z19,"員工代號:","")))+1,255),1)&REPT("*",LEN(MID(TRIM(SUBSTITUTE(Z19,"員工代號:","")),FIND(" ",TRIM(SUBSTITUTE(Z19,"員工代號:","")))+1,255))-2)&RIGHT(MID(TRIM(SUBSTITUTE(Z19,"員工代號:","")),FIND(" ",TRIM(SUBSTITUTE(Z19,"員工代號:","")))+1,255),1)))) | B19: 2026-06 | C19: =COUNTIFS(計算明細!$B:$B,$A19,計算明細!$L:$L,$B19,計算明細!$K:$K,1) | D19: =TEXT(SUMIFS(計算明細!$J:$J,計算明細!$B:$B,$A19,計算明細!$L:$L,$B19),"[h]:mm") | Z19: 員工代號:83737 羅開

Sheet 員工出勤明細表
A1: 總部
A2: 員工出勤明細表
A3: 員工代號:97668 郭靖
A4: 出勤日期:2026/06/01 至 2026/06/30
A5: 製表日期:2026/07/02
A6: 日期 | B6: 星期 | C6: 班次代號 | D6: 班次名稱 | E6: 上班 | F6: 下班 | G6: 備註
A7: 2026/06/01 | B7: 一
A8: 2026/06/02 | B8: 二
A9: 2026/06/03 | B9: 三
A10: 2026/06/04 | B10: 四
A11: 2026/06/05 | B11: 五
A12: 2026/06/06 | B12: 六
A13: 2026/06/07 | B13: 日
A14: 2026/06/08 | B14: 一 | C14: 2 | D14: 模具班 | E14: 07:53 | F14: 病假12:23
A15: 2026/06/08 | B15: 一 | C15: 3 | D15: 外出歸回班 | E15: 11:44 | F15: 12:01
A16: 2026/06/09 | B16: 二 | C16: 2 | D16: 模具班 | E16: 07:51 | F16: 19:41
A17: 2026/06/09 | B17: 二 | C17: 3 | D17: 外出歸回班 | E17: 14:27 | F17: 早退15:39
A18: 2026/06/10 | B18: 三 | C18: 2 | D18: 模具班 | E18: 07:51 | F18: 17:08
A19: 2026/06/11 | B19: 四 | C19: 2 | D19: 模具班 | E19: 07:56 | F19: 20:02
A20: 2026/06/12 | B20: 五 | C20: 2 | D20: 模具班 | E20: 07:55 | F20: 20:36
A21: 2026/06/13 | B21: 六
A22: 2026/06/14 | B22: 日
A23: 2026/06/15 | B23: 一 | C23: 2 | D23: 模具班 | E23: 07:53 | F23: 19:34
A24: 2026/06/16 | B24: 二 | C24: 2 | D24: 模具班 | E24: 07:55 | F24: 17:08
A25: 2026/06/17 | B25: 三 | C25: 2 | D25: 模具班 | E25: 07:56 | F25: 20:07
A26: 2026/06/18 | B26: 四 | C26: 2 | D26: 模具班 | E26: 07:53 | F26: 17:09
A27: 2026/06/19 | B27: 五
A28: 2026/06/20 | B28: 六
A29: 2026/06/21 | B29: 日
A30: 2026/06/22 | B30: 一 | C30: 2 | D30: 模具班 | E30: 07:53 | F30: 19:34
A31: 2026/06/23 | B31: 二 | C31: 2 | D31: 模具班 | E31: 07:53 | F31: 19:33
A32: 2026/06/24 | B32: 三 | C32: 2 | D32: 模具班 | E32: 07:56 | F32: 17:07
A33: 2026/06/25 | B33: 四 | C33: 2 | D33: 模具班 | E33: 07:55 | F33: 20:36
A34: 2026/06/26 | B34: 五 | C34: 2 | D34: 模具班 | E34: 07:55 | F34: 17:07
A35: 2026/06/27 | B35: 六 | C35: 2 | D35: 模具班 | E35: 遲到08:04 | F35: 早退15:08
A36: 2026/06/28 | B36: 日
A37: 2026/06/29 | B37: 一 | C37: 2 | D37: 模具班 | E37: 遲到08:25 | F37: 17:03
A38: 2026/06/30 | B38: 二 | C38: 2 | D38: 模具班 | E38: 07:55 | F38: 17:08
A39: 遲到次數: 2.00 早退次數: 2.00
A40: 遲到分鐘: 29.00 早退分鐘: 220.00
...

Sheet 計算明細
A1: 來源列 | B1: 員工 | C1: 日期 | D1: 星期 | E1: 上班原始 | F1: 下班原始 | G1: 上班時間 | H1: 下班時間 | I1: 計算下班 | J1: 工作時數 | K1: 每日計數 | L1: 每月 | AA1: 員工來源(隱藏)
A8: 7 | B8: =IF(AA8="","",IF(ISNUMBER(SEARCH("員工代號:",AA8)),"員工代號:","")&LEFT(LEFT(TRIM(SUBSTITUTE(AA8,"員工代號:","")),FIND(" ",TRIM(SUBSTITUTE(AA8,"員工代號:","")))-1),2)&REPT("*",MAX(1,LEN(LEFT(TRIM(SUBSTITUTE(AA8,"員工代號:","")),FIND(" ",TRIM(SUBSTITUTE(AA8,"員工代號:","")))-1))-4))&RIGHT(LEFT(TRIM(SUBSTITUTE(AA8,"員工代號:","")),FIND(" ",TRIM(SUBSTITUTE(AA8,"員工代號:","")))-1),2)&" "&IF(LEN(MID(TRIM(SUBSTITUTE(AA8,"員工代號:","")),FIND(" ",TRIM(SUBSTITUTE(AA8,"員工代號:","")))+1,255))<=1,"*",IF(LEN(MID(TRIM(SUBSTITUTE(AA8,"員工代號:","")),FIND(" ",TRIM(SUBSTITUTE(AA8,"員工代號:","")))+1,255))=2,LEFT(MID(TRIM(SUBSTITUTE(AA8,"員工代號:","")),FIND(" ",TRIM(SUBSTITUTE(AA8,"員工代號:","")))+1,255),1)&"*",LEFT(MID(TRIM(SUBSTITUTE(AA8,"員工代號:","")),FIND(" ",TRIM(SUBSTITUTE(AA8,"員工代號:","")))+1,255),1)&REPT("*",LEN(MID(TRIM(SUBSTITUTE(AA8,"員工代號:","")),FIND(" ",TRIM(SUBSTITUTE(AA8,"員工代號:","")))+1,255))-2)&RIGHT(MID(TRIM(SUBSTITUTE(AA8,"員工代號:","")),FIND(" ",TRIM(SUBSTITUTE(AA8,"員工代號:","")))+1,255),1)))) | C8: 46174 | D8: 一 | L8: 2026-06 | AA8: 員工代號:97668 郭靖
A9: 8 | B9: =IF(AA9="","",IF(ISNUMBER(SEARCH("員工代號:",AA9)),"員工代號:","")&LEFT(LEFT(TRIM(SUBSTITUTE(AA9,"員工代號:","")),FIND(" ",TRIM(SUBSTITUTE(AA9,"員工代號:","")))-1),2)&REPT("*",MAX(1,LEN(LEFT(TRIM(SUBSTITUTE(AA9,"員工代號:","")),FIND(" ",TRIM(SUBSTITUTE(AA9,"員工代號:","")))-1))-4))&RIGHT(LEFT(TRIM(SUBSTITUTE(AA9,"員工代號:","")),FIND(" ",TRIM(SUBSTITUTE(AA9,"員工代號:","")))-1),2)&" "&IF(LEN(MID(TRIM(SUBSTITUTE(AA9,"員工代號:","")),FIND(" ",TRIM(SUBSTITUTE(AA9,"員工代號:","")))+1,255))<=1,"*",IF(LEN(MID(TRIM(SUBSTITUTE(AA9,"員工代號:","")),FIND(" ",TRIM(SUBSTITUTE(AA9,"員工代號:","")))+1,255))=2,LEFT(MID(TRIM(SUBSTITUTE(AA9,"員工代號:","")),FIND(" ",TRIM(SUBSTITUTE(AA9,"員工代號:","")))+1,255),1)&"*",LEFT(MID(TRIM(SUBSTITUTE(AA9,"員工代號:","")),FIND(" ",TRIM(SUBSTITUTE(AA9,"員工代號:","")))+1,255),1)&REPT("*",LEN(MID(TRIM(SUBSTITUTE(AA9,"員工代號:","")),FIND(" ",TRIM(SUBSTITUTE(AA9,"員工代號:","")))+1,255))-2)&RIGHT(MID(TRIM(SUBSTITUTE(AA9,"員工代號:","")),FIND(" ",TRIM(SUBSTITUTE(AA9,"員工代號:","")))+1,255),1)))) | C9: 46175 | D9: 二 | L9: 2026-06 | AA9: 員工代號:97668 郭靖
A10: 9 | B10: =IF(AA10="","",IF(ISNUMBER(SEARCH("員工代號:",AA10)),"員工代號:","")&LEFT(LEFT(TRIM(SUBSTITUTE(AA10,"員工代號:","")),FIND(" ",TRIM(SUBSTITUTE(AA10,"員工代號:","")))-1),2)&REPT("*",MAX(1,LEN(LEFT(TRIM(SUBSTITUTE(AA10,"員工代號:","")),FIND(" ",TRIM(SUBSTITUTE(AA10,"員工代號:","")))-1))-4))&RIGHT(LEFT(TRIM(SUBSTITUTE(AA10,"員工代號:","")),FIND(" ",TRIM(SUBSTITUTE(AA10,"員工代號:","")))-1),2)&" "&IF(LEN(MID(TRIM(SUBSTITUTE(AA10,"員工代號:","")),FIND(" ",TRIM(SUBSTITUTE(AA10,"員工代號:","")))+1,255))<=1,"*",IF(LEN(MID(TRIM(SUBSTITUTE(AA10,"員工代號:","")),FIND(" ",TRIM(SUBSTITUTE(AA10,"員工代號:","")))+1,255))=2,LEFT(MID(TRIM(SUBSTITUTE(AA10,"員工代號:","")),FIND(" ",TRIM(SUBSTITUTE(AA10,"員工代號:","")))+1,255),1)&"*",LEFT(MID(TRIM(SUBSTITUTE(AA10,"員工代號:","")),FIND(" ",TRIM(SUBSTITUTE(AA10,"員工代號:","")))+1,255),1)&REPT("*",LEN(MID(TRIM(SUBSTITUTE(AA10,"員工代號:","")),FIND(" ",TRIM(SUBSTITUTE(AA10,"員工代號:","")))+1,255))-2)&RIGHT(MID(TRIM(SUBSTITUTE(AA10,"員工代號:","")),FIND(" ",TRIM(SUBSTITUTE(AA10,"員工代號:","")))+1,255),1)))) | C10: 46176 | D10: 三 | L10: 2026-06 | AA10: 員工代號:97668 郭靖
A11: 10 | B11: =IF(AA11="","",IF(ISNUMBER(SEARCH("員工代號:",AA11)),"員工代號:","")&LEFT(LEFT(TRIM(SUBSTITUTE(AA11,"員工代號:","")),FIND(" ",TRIM(SUBSTITUTE(AA11,"員工代號:","")))-1),2)&REPT("*",MAX(1,LEN(LEFT(TRIM(SUBSTITUTE(AA11,"員工代號:","")),FIND(" ",TRIM(SUBSTITUTE(AA11,"員工代號:","")))-1))-4))&RIGHT(LEFT(TRIM(SUBSTITUTE(AA11,"員工代號:","")),FIND(" ",TRIM(SUBSTITUTE(AA11,"員工代號:","")))-1),2)&" "&IF(LEN(MID(TRIM(SUBSTITUTE(AA11,"員工代號:","")),FIND(" ",TRIM(SUBSTITUTE(AA11,"員工代號:","")))+1,255))<=1,"*",IF(LEN(MID(TRIM(SUBSTITUTE(AA11,"員工代號:","")),FIND(" ",TRIM(SUBSTITUTE(AA11,"員工代號:","")))+1,255))=2,LEFT(MID(TRIM(SUBSTITUTE(AA11,"員工代號:","")),FIND(" ",TRIM(SUBSTITUTE(AA11,"員工代號:","")))+1,255),1)&"*",LEFT(MID(TRIM(SUBSTITUTE(AA11,"員工代號:","")),FIND(" ",TRIM(SUBSTITUTE(AA11,"員工代號:","")))+1,255),1)&REPT("*",LEN(MID(TRIM(SUBSTITUTE(AA11,"員工代號:","")),FIND(" ",TRIM(SUBSTITUTE(AA11,"員工代號:","")))+1,255))-2)&RIGHT(MID(TRIM(SUBSTITUTE(AA11,"員工代號:","")),FIND(" ",TRIM(SUBSTITUTE(AA11,"員工代號:","")))+1,255),1)))) | C11: 46177 | D11: 四 | L11: 2026-06 | AA11: 員工代號:97668 郭靖
A12: 11 | B12: =IF(AA12="","",IF(ISNUMBER(SEARCH("員工代號:",AA12)),"員工代號:","")&LEFT(LEFT(TRIM(SUBSTITUTE(AA12,"員工代號:","")),FIND(" ",TRIM(SUBSTITUTE(AA12,"員工代號:","")))-1),2)&REPT("*",MAX(1,LEN(LEFT(TRIM(SUBSTITUTE(AA12,"員工代號:","")),FIND(" ",TRIM(SUBSTITUTE(AA12,"員工代號:","")))-1))-4))&RIGHT(LEFT(TRIM(SUBSTITUTE(AA12,"員工代號:","")),FIND(" ",TRIM(SUBSTITUTE(AA12,"員工代號:","")))-1),2)&" "&IF(LEN(MID(TRIM(SUBSTITUTE(AA12,"員工代號:","")),FIND(" ",TRIM(SUBSTITUTE(AA12,"員工代號:","")))+1,255))<=1,"*",IF(LEN(MID(TRIM(SUBSTITUTE(AA12,"員工代號:","")),FIND(" ",TRIM(SUBSTITUTE(AA12,"員工代號:","")))+1,255))=2,LEFT(MID(TRIM(SUBSTITUTE(AA12,"員工代號:","")),FIND(" ",TRIM(SUBSTITUTE(AA12,"員工代號:","")))+1,255),1)&"*",LEFT(MID(TRIM(SUBSTITUTE(AA12,"員工代號:","")),FIND(" ",TRIM(SUBSTITUTE(AA12,"員工代號:","")))+1,255),1)&REPT("*",LEN(MID(TRIM(SUBSTITUTE(AA12,"員工代號:","")),FIND(" ",TRIM(SUBSTITUTE(AA12,"員工代號:","")))+1,255))-2)&RIGHT(MID(TRIM(SUBSTITUTE(AA12,"員工代號:","")),FIND(" ",TRIM(SUBSTITUTE(AA12,"員工代號:","")))+1,255),1)))) | C12: 46178 | D12: 五 | L12: 2026-06 | AA12: 員工代號:97668 郭靖
A13: 12 | B13: =IF(AA13="","",IF(ISNUMBER(SEARCH("員工代號:",AA13)),"員工代號:","")&LEFT(LEFT(TRIM(SUBSTITUTE(AA13,"員工代號:","")),FIND(" ",TRIM(SUBSTITUTE(AA13,"員工代號:","")))-1),2)&REPT("*",MAX(1,LEN(LEFT(TRIM(SUBSTITUTE(AA13,"員工代號:","")),FIND(" ",TRIM(SUBSTITUTE(AA13,"員工代號:","")))-1))-4))&RIGHT(LEFT(TRIM(SUBSTITUTE(AA13,"員工代號:","")),FIND(" ",TRIM(SUBSTITUTE(AA13,"員工代號:","")))-1),2)&" "&IF(LEN(MID(TRIM(SUBSTITUTE(AA13,"員工代號:","")),FIND(" ",TRIM(SUBSTITUTE(AA13,"員工代號:","")))+1,255))<=1,"*",IF(LEN(MID(TRIM(SUBSTITUTE(AA13,"員工代號:","")),FIND(" ",TRIM(SUBSTITUTE(AA13,"員工代號:","")))+1,255))=2,LEFT(MID(TRIM(SUBSTITUTE(AA13,"員工代號:","")),FIND(" ",TRIM(SUBSTITUTE(AA13,"員工代號:","")))+1,255),1)&"*",LEFT(MID(TRIM(SUBSTITUTE(AA13,"員工代號:","")),FIND(" ",TRIM(SUBSTITUTE(AA13,"員工代號:","")))+1,255),1)&REPT("*",LEN(MID(TRIM(SUBSTITUTE(AA13,"員工代號:","")),FIND(" ",TRIM(SUBSTITUTE(AA13,"員工代號:","")))+1,255))-2)&RIGHT(MID(TRIM(SUBSTITUTE(AA13,"員工代號:","")),FIND(" ",TRIM(SUBSTITUTE(AA13,"員工代號:","")))+1,255),1)))) | C13: 46179 | D13: 六 | L13: 2026-06 | AA13: 員工代號:97668 郭靖
A14: 13 | B14: =IF(AA14="","",IF(ISNUMBER(SEARCH("員工代號:",AA14)),"員工代號:","")&LEFT(LEFT(TRIM(SUBSTITUTE(AA14,"員工代號:","")),FIND(" ",TRIM(SUBSTITUTE(AA14,"員工代號:","")))-1),2)&REPT("*",MAX(1,LEN(LEFT(TRIM(SUBSTITUTE(AA14,"員工代號:","")),FIND(" ",TRIM(SUBSTITUTE(AA14,"員工代號:","")))-1))-4))&RIGHT(LEFT(TRIM(SUBSTITUTE(AA14,"員工代號:","")),FIND(" ",TRIM(SUBSTITUTE(AA14,"員工代號:","")))-1),2)&" "&IF(LEN(MID(TRIM(SUBSTITUTE(AA14,"員工代號:","")),FIND(" ",TRIM(SUBSTITUTE(AA14,"員工代號:","")))+1,255))<=1,"*",IF(LEN(MID(TRIM(SUBSTITUTE(AA14,"員工代號:","")),FIND(" ",TRIM(SUBSTITUTE(AA14,"員工代號:","")))+1,255))=2,LEFT(MID(TRIM(SUBSTITUTE(AA14,"員工代號:","")),FIND(" ",TRIM(SUBSTITUTE(AA14,"員工代號:","")))+1,255),1)&"*",LEFT(MID(TRIM(SUBSTITUTE(AA14,"員工代號:","")),FIND(" ",TRIM(SUBSTITUTE(AA14,"員工代號:","")))+1,255),1)&REPT("*",LEN(MID(TRIM(SUBSTITUTE(AA14,"員工代號:","")),FIND(" ",TRIM(SUBSTITUTE(AA14,"員工代號:","")))+1,255))-2)&RIGHT(MID(TRIM(SUBSTITUTE(AA14,"員工代號:","")),FIND(" ",TRIM(SUBSTITUTE(AA14,"員工代號:","")))+1,255),1)))) | C14: 46180 | D14: 日 | L14: 2026-06 | AA14: 員工代號:97668 郭靖
A15: 14 | B15: =IF(AA15="","",IF(ISNUMBER(SEARCH("員工代號:",AA15)),"員工代號:","")&LEFT(LEFT(TRIM(SUBSTITUTE(AA15,"員工代號:","")),FIND(" ",TRIM(SUBSTITUTE(AA15,"員工代號:","")))-1),2)&REPT("*",MAX(1,LEN(LEFT(TRIM(SUBSTITUTE(AA15,"員工代號:","")),FIND(" ",TRIM(SUBSTITUTE(AA15,"員工代號:","")))-1))-4))&RIGHT(LEFT(TRIM(SUBSTITUTE(AA15,"員工代號:","")),FIND(" ",TRIM(SUBSTITUTE(AA15,"員工代號:","")))-1),2)&" "&IF(LEN(MID(TRIM(SUBSTITUTE(AA15,"員工代號:","")),FIND(" ",TRIM(SUBSTITUTE(AA15,"員工代號:","")))+1,255))<=1,"*",IF(LEN(MID(TRIM(SUBSTITUTE(AA15,"員工代號:","")),FIND(" ",TRIM(SUBSTITUTE(AA15,"員工代號:","")))+1,255))=2,LEFT(MID(TRIM(SUBSTITUTE(AA15,"員工代號:","")),FIND(" ",TRIM(SUBSTITUTE(AA15,"員工代號:","")))+1,255),1)&"*",LEFT(MID(TRIM(SUBSTITUTE(AA15,"員工代號:","")),FIND(" ",TRIM(SUBSTITUTE(AA15,"員工代號:","")))+1,255),1)&REPT("*",LEN(MID(TRIM(SUBSTITUTE(AA15,"員工代號:","")),FIND(" ",TRIM(SUBSTITUTE(AA15,"員工代號:","")))+1,255))-2)&RIGHT(MID(TRIM(SUBSTITUTE(AA15,"員工代號:","")),FIND(" ",TRIM(SUBSTITUTE(AA15,"員工代號:","")))+1,255),1)))) | C15: 46181 | D15: 一 | E15: 07:53 | F15: 病假12:23 | G15: 0.32847222 | H15: 0.51597222 | I15: 0.51597222 | J15: 0.1875 | K15: 1 | L15: 2026-06 | AA15: 員工代號:97668 郭靖
A16: 15 | B16: =IF(AA16="","",IF(ISNUMBER(SEARCH("員工代號:",AA16)),"員工代號:","")&LEFT(LEFT(TRIM(SUBSTITUTE(AA16,"員工代號:","")),FIND(" ",TRIM(SUBSTITUTE(AA16,"員工代號:","")))-1),2)&REPT("*",MAX(1,LEN(LEFT(TRIM(SUBSTITUTE(AA16,"員工代號:","")),FIND(" ",TRIM(SUBSTITUTE(AA16,"員工代號:","")))-1))-4))&RIGHT(LEFT(TRIM(SUBSTITUTE(AA16,"員工代號:","")),FIND(" ",TRIM(SUBSTITUTE(AA16,"員工代號:","")))-1),2)&" "&IF(LEN(MID(TRIM(SUBSTITUTE(AA16,"員工代號:","")),FIND(" ",TRIM(SUBSTITUTE(AA16,"員工代號:","")))+1,255))<=1,"*",IF(LEN(MID(TRIM(SUBSTITUTE(AA16,"員工代號:","")),FIND(" ",TRIM(SUBSTITUTE(AA16,"員工代號:","")))+1,255))=2,LEFT(MID(TRIM(SUBSTITUTE(AA16,"員工代號:","")),FIND(" ",TRIM(SUBSTITUTE(AA16,"員工代號:","")))+1,255),1)&"*",LEFT(MID(TRIM(SUBSTITUTE(AA16,"員工代號:","")),FIND(" ",TRIM(SUBSTITUTE(AA16,"員工代號:","")))+1,255),1)&REPT("*",LEN(MID(TRIM(SUBSTITUTE(AA16,"員工代號:","")),FIND(" ",TRIM(SUBSTITUTE(AA16,"員工代號:","")))+1,255))-2)&RIGHT(MID(TRIM(SUBSTITUTE(AA16,"員工代號:","")),FIND(" ",TRIM(SUBSTITUTE(AA16,"員工代號:","")))+1,255),1)))) | C16: 46181 | D16: 一 | E16: 11:44 | F16: 12:01 | G16: 0.48888889 | H16: 0.50069444 | I16: 0.50069444 | J16: 0.011805556 | K16: 0 | L16: 2026-06 | AA16: 員工代號:97668 郭靖
A17: 16 | B17: =IF(AA17="","",IF(ISNUMBER(SEARCH("員工代號:",AA17)),"員工代號:","")&LEFT(LEFT(TRIM(SUBSTITUTE(AA17,"員工代號:","")),FIND(" ",TRIM(SUBSTITUTE(AA17,"員工代號:","")))-1),2)&REPT("*",MAX(1,LEN(LEFT(TRIM(SUBSTITUTE(AA17,"員工代號:","")),FIND(" ",TRIM(SUBSTITUTE(AA17,"員工代號:","")))-1))-4))&RIGHT(LEFT(TRIM(SUBSTITUTE(AA17,"員工代號:","")),FIND(" ",TRIM(SUBSTITUTE(AA17,"員工代號:","")))-1),2)&" "&IF(LEN(MID(TRIM(SUBSTITUTE(AA17,"員工代號:","")),FIND(" ",TRIM(SUBSTITUTE(AA17,"員工代號:","")))+1,255))<=1,"*",IF(LEN(MID(TRIM(SUBSTITUTE(AA17,"員工代號:","")),FIND(" ",TRIM(SUBSTITUTE(AA17,"員工代號:","")))+1,255))=2,LEFT(MID(TRIM(SUBSTITUTE(AA17,"員工代號:","")),FIND(" ",TRIM(SUBSTITUTE(AA17,"員工代號:","")))+1,255),1)&"*",LEFT(MID(TRIM(SUBSTITUTE(AA17,"員工代號:","")),FIND(" ",TRIM(SUBSTITUTE(AA17,"員工代號:","")))+1,255),1)&REPT("*",LEN(MID(TRIM(SUBSTITUTE(AA17,"員工代號:","")),FIND(" ",TRIM(SUBSTITUTE(AA17,"員工代號:","")))+1,255))-2)&RIGHT(MID(TRIM(SUBSTITUTE(AA17,"員工代號:","")),FIND(" ",TRIM(SUBSTITUTE(AA17,"員工代號:","")))+1,255),1)))) | C17: 46182 | D17: 二 | E17: 07:51 | F17: 19:41 | G17: 0.32708333 | H17: 0.82013889 | I17: 0.8125 | J17: 0.48541667 | K17: 1 | L17: 2026-06 | AA17: 員工代號:97668 郭靖
A18: 17 | B18: =IF(AA18="","",IF(ISNUMBER(SEARCH("員工代號:",AA18)),"員工代號:","")&LEFT(LEFT(TRIM(SUBSTITUTE(AA18,"員工代號:","")),FIND(" ",TRIM(SUBSTITUTE(AA18,"員工代號:","")))-1),2)&REPT("*",MAX(1,LEN(LEFT(TRIM(SUBSTITUTE(AA18,"員工代號:","")),FIND(" ",TRIM(SUBSTITUTE(AA18,"員工代號:","")))-1))-4))&RIGHT(LEFT(TRIM(SUBSTITUTE(AA18,"員工代號:","")),FIND(" ",TRIM(SUBSTITUTE(AA18,"員工代號:","")))-1),2)&" "&IF(LEN(MID(TRIM(SUBSTITUTE(AA18,"員工代號:","")),FIND(" ",TRIM(SUBSTITUTE(AA18,"員工代號:","")))+1,255))<=1,"*",IF(LEN(MID(TRIM(SUBSTITUTE(AA18,"員工代號:","")),FIND(" ",TRIM(SUBSTITUTE(AA18,"員工代號:","")))+1,255))=2,LEFT(MID(TRIM(SUBSTITUTE(AA18,"員工代號:","")),FIND(" ",TRIM(SUBSTITUTE(AA18,"員工代號:","")))+1,255),1)&"*",LEFT(MID(TRIM(SUBSTITUTE(AA18,"員工代號:","")),FIND(" ",TRIM(SUBSTITUTE(AA18,"員工代號:","")))+1,255),1)&REPT("*",LEN(MID(TRIM(SUBSTITUTE(AA18,"員工代號:","")),FIND(" ",TRIM(SUBSTITUTE(AA18,"員工代號:","")))+1,255))-2)&RIGHT(MID(TRIM(SUBSTITUTE(AA18,"員工代號:","")),FIND(" ",TRIM(SUBSTITUTE(AA18,"員工代號:","")))+1,255),1)))) | C18: 46182 | D18: 二 | E18: 14:27 | F18: 早退15:39 | G18: 0.60208333 | H18: 0.65208333 | I18: 0.65208333 | J18: 0.05 | K18: 0 | L18: 2026-06 | AA18: 員工代號:97668 郭靖
A19: 18 | B19: =IF(AA19="","",IF(ISNUMBER(SEARCH("員工代號:",AA19)),"員工代號:","")&LEFT(LEFT(TRIM(SUBSTITUTE(AA19,"員工代號:","")),FIND(" ",TRIM(SUBSTITUTE(AA19,"員工代號:","")))-1),2)&REPT("*",MAX(1,LEN(LEFT(TRIM(SUBSTITUTE(AA19,"員工代號:","")),FIND(" ",TRIM(SUBSTITUTE(AA19,"員工代號:","")))-1))-4))&RIGHT(LEFT(TRIM(SUBSTITUTE(AA19,"員工代號:","")),FIND(" ",TRIM(SUBSTITUTE(AA19,"員工代號:","")))-1),2)&" "&IF(LEN(MID(TRIM(SUBSTITUTE(AA19,"員工代號:","")),FIND(" ",TRIM(SUBSTITUTE(AA19,"員工代號:","")))+1,255))<=1,"*",IF(LEN(MID(TRIM(SUBSTITUTE(AA19,"員工代號:","")),FIND(" ",TRIM(SUBSTITUTE(AA19,"員工代號:","")))+1,255))=2,LEFT(MID(TRIM(SUBSTITUTE(AA19,"員工代號:","")),FIND(" ",TRIM(SUBSTITUTE(AA19,"員工代號:","")))+1,255),1)&"*",LEFT(MID(TRIM(SUBSTITUTE(AA19,"員工代號:","")),FIND(" ",TRIM(SUBSTITUTE(AA19,"員工代號:","")))+1,255),1)&REPT("*",LEN(MID(TRIM(SUBSTITUTE(AA19,"員工代號:","")),FIND(" ",TRIM(SUBSTITUTE(AA19,"員工代號:","")))+1,255))-2)&RIGHT(MID(TRIM(SUBSTITUTE(AA19,"員工代號:","")),FIND(" ",TRIM(SUBSTITUTE(AA19,"員工代號:","")))+1,255),1)))) | C19: 46183 | D19: 三 | E19: 07:51 | F19: 17:08 | G19: 0.32708333 | H19: 0.71388889 | I19: 0.71388889 | J19: 0.38680556 | K19: 1 | L19: 2026-06 | AA19: 員工代號:97668 郭靖
A20: 19 | B20: =IF(AA20="","",IF(ISNUMBER(SEARCH("員工代號:",AA20)),"員工代號:","")&LEFT(LEFT(TRIM(SUBSTITUTE(AA20,"員工代號:","")),FIND(" ",TRIM(SUBSTITUTE(AA20,"員工代號:","")))-1),2)&REPT("*",MAX(1,LEN(LEFT(TRIM(SUBSTITUTE(AA20,"員工代號:","")),FIND(" ",TRIM(SUBSTITUTE(AA20,"員工代號:","")))-1))-4))&RIGHT(LEFT(TRIM(SUBSTITUTE(AA20,"員工代號:","")),FIND(" ",TRIM(SUBSTITUTE(AA20,"員工代號:","")))-1),2)&" "&IF(LEN(MID(TRIM(SUBSTITUTE(AA20,"員工代號:","")),FIND(" ",TRIM(SUBSTITUTE(AA20,"員工代號:","")))+1,255))<=1,"*",IF(LEN(MID(TRIM(SUBSTITUTE(AA20,"員工代號:","")),FIND(" ",TRIM(SUBSTITUTE(AA20,"員工代號:","")))+1,255))=2,LEFT(MID(TRIM(SUBSTITUTE(AA20,"員工代號:","")),FIND(" ",TRIM(SUBSTITUTE(AA20,"員工代號:","")))+1,255),1)&"*",LEFT(MID(TRIM(SUBSTITUTE(AA20,"員工代號:","")),FIND(" ",TRIM(SUBSTITUTE(AA20,"員工代號:","")))+1,255),1)&REPT("*",LEN(MID(TRIM(SUBSTITUTE(AA20,"員工代號:","")),FIND(" ",TRIM(SUBSTITUTE(AA20,"員工代號:","")))+1,255))-2)&RIGHT(MID(TRIM(SUBSTITUTE(AA20,"員工代號:","")),FIND(" ",TRIM(SUBSTITUTE(AA20,"員工代號:","")))+1,255),1)))) | C20: 46184 | D20: 四 | E20: 07:56 | F20: 20:02 | G20: 0.33055556 | H20: 0.83472222 | I20: 0.8125 | J20: 0.48194444 | K20: 1 | L20: 2026-06 | AA20: 員工代號:97668 郭靖
A21: 20 | B21: =IF(AA21="","",IF(ISNUMBER(SEARCH("員工代號:",AA21)),"員工代號:","")&LEFT(LEFT(TRIM(SUBSTITUTE(AA21,"員工代號:","")),FIND(" ",TRIM(SUBSTITUTE(AA21,"員工代號:","")))-1),2)&REPT("*",MAX(1,LEN(LEFT(TRIM(SUBSTITUTE(AA21,"員工代號:","")),FIND(" ",TRIM(SUBSTITUTE(AA21,"員工代號:","")))-1))-4))&RIGHT(LEFT(TRIM(SUBSTITUTE(AA21,"員工代號:","")),FIND(" ",TRIM(SUBSTITUTE(AA21,"員工代號:","")))-1),2)&" "&IF(LEN(MID(TRIM(SUBSTITUTE(AA21,"員工代號:","")),FIND(" ",TRIM(SUBSTITUTE(AA21,"員工代號:","")))+1,255))<=1,"*",IF(LEN(MID(TRIM(SUBSTITUTE(AA21,"員工代號:","")),FIND(" ",TRIM(SUBSTITUTE(AA21,"員工代號:","")))+1,255))=2,LEFT(MID(TRIM(SUBSTITUTE(AA21,"員工代號:","")),FIND(" ",TRIM(SUBSTITUTE(AA21,"員工代號:","")))+1,255),1)&"*",LEFT(MID(TRIM(SUBSTITUTE(AA21,"員工代號:","")),FIND(" ",TRIM(SUBSTITUTE(AA21,"員工代號:","")))+1,255),1)&REPT("*",LEN(MID(TRIM(SUBSTITUTE(AA21,"員工代號:","")),FIND(" ",TRIM(SUBSTITUTE(AA21,"員工代號:","")))+1,255))-2)&RIGHT(MID(TRIM(SUBSTITUTE(AA21,"員工代號:","")),FIND(" ",TRIM(SUBSTITUTE(AA21,"員工代號:","")))+1,255),1)))) | C21: 46185 | D21: 五 | E21: 07:55 | F21: 20:36 | G21: 0.32986111 | H21: 0.85833333 | I21: 0.8125 | J21: 0.48263889 | K21: 1 | L21: 2026-06 | AA21: 員工代號:97668 郭靖
A22: 21 | B22: =IF(AA22="","",IF(ISNUMBER(SEARCH("員工代號:",AA22)),"員工代號:","")&LEFT(LEFT(TRIM(SUBSTITUTE(AA22,"員工代號:","")),FIND(" ",TRIM(SUBSTITUTE(AA22,"員工代號:","")))-1),2)&REPT("*",MAX(1,LEN(LEFT(TRIM(SUBSTITUTE(AA22,"員工代號:","")),FIND(" ",TRIM(SUBSTITUTE(AA22,"員工代號:","")))-1))-4))&RIGHT(LEFT(TRIM(SUBSTITUTE(AA22,"員工代號:","")),FIND(" ",TRIM(SUBSTITUTE(AA22,"員工代號:","")))-1),2)&" "&IF(LEN(MID(TRIM(SUBSTITUTE(AA22,"員工代號:","")),FIND(" ",TRIM(SUBSTITUTE(AA22,"員工代號:","")))+1,255))<=1,"*",IF(LEN(MID(TRIM(SUBSTITUTE(AA22,"員工代號:","")),FIND(" ",TRIM(SUBSTITUTE(AA22,"員工代號:","")))+1,255))=2,LEFT(MID(TRIM(SUBSTITUTE(AA22,"員工代號:","")),FIND(" ",TRIM(SUBSTITUTE(AA22,"員工代號:","")))+1,255),1)&"*",LEFT(MID(TRIM(SUBSTITUTE(AA22,"員工代號:","")),FIND(" ",TRIM(SUBSTITUTE(AA22,"員工代號:","")))+1,255),1)&REPT("*",LEN(MID(TRIM(SUBSTITUTE(AA22,"員工代號:","")),FIND(" ",TRIM(SUBSTITUTE(AA22,"員工代號:","")))+1,255))-2)&RIGHT(MID(TRIM(SUBSTITUTE(AA22,"員工代號:","")),FIND(" ",TRIM(SUBSTITUTE(AA22,"員工代號:","")))+1,255),1)))) | C22: 46186 | D22: 六 | L22: 2026-06 | AA22: 員工代號:97668 郭靖
A23: 22 | B23: =IF(AA23="","",IF(ISNUMBER(SEARCH("員工代號:",AA23)),"員工代號:","")&LEFT(LEFT(TRIM(SUBSTITUTE(AA23,"員工代號:","")),FIND(" ",TRIM(SUBSTITUTE(AA23,"員工代號:","")))-1),2)&REPT("*",MAX(1,LEN(LEFT(TRIM(SUBSTITUTE(AA23,"員工代號:","")),FIND(" ",TRIM(SUBSTITUTE(AA23,"員工代號:","")))-1))-4))&RIGHT(LEFT(TRIM(SUBSTITUTE(AA23,"員工代號:","")),FIND(" ",TRIM(SUBSTITUTE(AA23,"員工代號:","")))-1),2)&" "&IF(LEN(MID(TRIM(SUBSTITUTE(AA23,"員工代號:","")),FIND(" ",TRIM(SUBSTITUTE(AA23,"員工代號:","")))+1,255))<=1,"*",IF(LEN(MID(TRIM(SUBSTITUTE(AA23,"員工代號:","")),FIND(" ",TRIM(SUBSTITUTE(AA23,"員工代號:","")))+1,255))=2,LEFT(MID(TRIM(SUBSTITUTE(AA23,"員工代號:","")),FIND(" ",TRIM(SUBSTITUTE(AA23,"員工代號:","")))+1,255),1)&"*",LEFT(MID(TRIM(SUBSTITUTE(AA23,"員工代號:","")),FIND(" ",TRIM(SUBSTITUTE(AA23,"員工代號:","")))+1,255),1)&REPT("*",LEN(MID(TRIM(SUBSTITUTE(AA23,"員工代號:","")),FIND(" ",TRIM(SUBSTITUTE(AA23,"員工代號:","")))+1,255))-2)&RIGHT(MID(TRIM(SUBSTITUTE(AA23,"員工代號:","")),FIND(" ",TRIM(SUBSTITUTE(AA23,"員工代號:","")))+1,255),1)))) | C23: 46187 | D23: 日 | L23: 2026-06 | AA23: 員工代號:97668 郭靖
A24: 23 | B24: =IF(AA24="","",IF(ISNUMBER(SEARCH("員工代號:",AA24)),"員工代號:","")&LEFT(LEFT(TRIM(SUBSTITUTE(AA24,"員工代號:","")),FIND(" ",TRIM(SUBSTITUTE(AA24,"員工代號:","")))-1),2)&REPT("*",MAX(1,LEN(LEFT(TRIM(SUBSTITUTE(AA24,"員工代號:","")),FIND(" ",TRIM(SUBSTITUTE(AA24,"員工代號:","")))-1))-4))&RIGHT(LEFT(TRIM(SUBSTITUTE(AA24,"員工代號:","")),FIND(" ",TRIM(SUBSTITUTE(AA24,"員工代號:","")))-1),2)&" "&IF(LEN(MID(TRIM(SUBSTITUTE(AA24,"員工代號:","")),FIND(" ",TRIM(SUBSTITUTE(AA24,"員工代號:","")))+1,255))<=1,"*",IF(LEN(MID(TRIM(SUBSTITUTE(AA24,"員工代號:","")),FIND(" ",TRIM(SUBSTITUTE(AA24,"員工代號:","")))+1,255))=2,LEFT(MID(TRIM(SUBSTITUTE(AA24,"員工代號:","")),FIND(" ",TRIM(SUBSTITUTE(AA24,"員工代號:","")))+1,255),1)&"*",LEFT(MID(TRIM(SUBSTITUTE(AA24,"員工代號:","")),FIND(" ",TRIM(SUBSTITUTE(AA24,"員工代號:","")))+1,255),1)&REPT("*",LEN(MID(TRIM(SUBSTITUTE(AA24,"員工代號:","")),FIND(" ",TRIM(SUBSTITUTE(AA24,"員工代號:","")))+1,255))-2)&RIGHT(MID(TRIM(SUBSTITUTE(AA24,"員工代號:","")),FIND(" ",TRIM(SUBSTITUTE(AA24,"員工代號:","")))+1,255),1)))) | C24: 46188 | D24: 一 | E24: 07:53 | F24: 19:34 | G24: 0.32847222 | H24: 0.81527778 | I24: 0.8125 | J24: 0.48402778 | K24: 1 | L24: 2026-06 | AA24: 員工代號:97668 郭靖
A25: 24 | B25: =IF(AA25="","",IF(ISNUMBER(SEARCH("員工代號:",AA25)),"員工代號:","")&LEFT(LEFT(TRIM(SUBSTITUTE(AA25,"員工代號:","")),FIND(" ",TRIM(SUBSTITUTE(AA25,"員工代號:","")))-1),2)&REPT("*",MAX(1,LEN(LEFT(TRIM(SUBSTITUTE(AA25,"員工代號:","")),FIND(" ",TRIM(SUBSTITUTE(AA25,"員工代號:","")))-1))-4))&RIGHT(LEFT(TRIM(SUBSTITUTE(AA25,"員工代號:","")),FIND(" ",TRIM(SUBSTITUTE(AA25,"員工代號:","")))-1),2)&" "&IF(LEN(MID(TRIM(SUBSTITUTE(AA25,"員工代號:","")),FIND(" ",TRIM(SUBSTITUTE(AA25,"員工代號:","")))+1,255))<=1,"*",IF(LEN(MID(TRIM(SUBSTITUTE(AA25,"員工代號:","")),FIND(" ",TRIM(SUBSTITUTE(AA25,"員工代號:","")))+1,255))=2,LEFT(MID(TRIM(SUBSTITUTE(AA25,"員工代號:","")),FIND(" ",TRIM(SUBSTITUTE(AA25,"員工代號:","")))+1,255),1)&"*",LEFT(MID(TRIM(SUBSTITUTE(AA25,"員工代號:","")),FIND(" ",TRIM(SUBSTITUTE(AA25,"員工代號:","")))+1,255),1)&REPT("*",LEN(MID(TRIM(SUBSTITUTE(AA25,"員工代號:","")),FIND(" ",TRIM(SUBSTITUTE(AA25,"員工代號:","")))+1,255))-2)&RIGHT(MID(TRIM(SUBSTITUTE(AA25,"員工代號:","")),FIND(" ",TRIM(SUBSTITUTE(AA25,"員工代號:","")))+1,255),1)))) | C25: 46189 | D25: 二 | E25: 07:55 | F25: 17:08 | G25: 0.32986111 | H25: 0.71388889 | I25: 0.71388889 | J25: 0.38402778 | K25: 1 | L25: 2026-06 | AA25: 員工代號:97668 郭靖
A26: 25 | B26: =IF(AA26="","",IF(ISNUMBER(SEARCH("員工代號:",AA26)),"員工代號:","")&LEFT(LEFT(TRIM(SUBSTITUTE(AA26,"員工代號:","")),FIND(" ",TRIM(SUBSTITUTE(AA26,"員工代號:","")))-1),2)&REPT("*",MAX(1,LEN(LEFT(TRIM(SUBSTITUTE(AA26,"員工代號:","")),FIND(" ",TRIM(SUBSTITUTE(AA26,"員工代號:","")))-1))-4))&RIGHT(LEFT(TRIM(SUBSTITUTE(AA26,"員工代號:","")),FIND(" ",TRIM(SUBSTITUTE(AA26,"員工代號:","")))-1),2)&" "&IF(LEN(MID(TRIM(SUBSTITUTE(AA26,"員工代號:","")),FIND(" ",TRIM(SUBSTITUTE(AA26,"員工代號:","")))+1,255))<=1,"*",IF(LEN(MID(TRIM(SUBSTITUTE(AA26,"員工代號:","")),FIND(" ",TRIM(SUBSTITUTE(AA26,"員工代號:","")))+1,255))=2,LEFT(MID(TRIM(SUBSTITUTE(AA26,"員工代號:","")),FIND(" ",TRIM(SUBSTITUTE(AA26,"員工代號:","")))+1,255),1)&"*",LEFT(MID(TRIM(SUBSTITUTE(AA26,"員工代號:","")),FIND(" ",TRIM(SUBSTITUTE(AA26,"員工代號:","")))+1,255),1)&REPT("*",LEN(MID(TRIM(SUBSTITUTE(AA26,"員工代號:","")),FIND(" ",TRIM(SUBSTITUTE(AA26,"員工代號:","")))+1,255))-2)&RIGHT(MID(TRIM(SUBSTITUTE(AA26,"員工代號:","")),FIND(" ",TRIM(SUBSTITUTE(AA26,"員工代號:","")))+1,255),1)))) | C26: 46190 | D26: 三 | E26: 07:56 | F26: 20:07 | G26: 0.33055556 | H26: 0.83819444 | I26: 0.8125 | J26: 0.48194444 | K26: 1 | L26: 2026-06 | AA26: 員工代號:97668 郭靖
A27: 26 | B27: =IF(AA27="","",IF(ISNUMBER(SEARCH("員工代號:",AA27)),"員工代號:","")&LEFT(LEFT(TRIM(SUBSTITUTE(AA27,"員工代號:","")),FIND(" ",TRIM(SUBSTITUTE(AA27,"員工代號:","")))-1),2)&REPT("*",MAX(1,LEN(LEFT(TRIM(SUBSTITUTE(AA27,"員工代號:","")),FIND(" ",TRIM(SUBSTITUTE(AA27,"員工代號:","")))-1))-4))&RIGHT(LEFT(TRIM(SUBSTITUTE(AA27,"員工代號:","")),FIND(" ",TRIM(SUBSTITUTE(AA27,"員工代號:","")))-1),2)&" "&IF(LEN(MID(TRIM(SUBSTITUTE(AA27,"員工代號:","")),FIND(" ",TRIM(SUBSTITUTE(AA27,"員工代號:","")))+1,255))<=1,"*",IF(LEN(MID(TRIM(SUBSTITUTE(AA27,"員工代號:","")),FIND(" ",TRIM(SUBSTITUTE(AA27,"員工代號:","")))+1,255))=2,LEFT(MID(TRIM(SUBSTITUTE(AA27,"員工代號:","")),FIND(" ",TRIM(SUBSTITUTE(AA27,"員工代號:","")))+1,255),1)&"*",LEFT(MID(TRIM(SUBSTITUTE(AA27,"員工代號:","")),FIND(" ",TRIM(SUBSTITUTE(AA27,"員工代號:","")))+1,255),1)&REPT("*",LEN(MID(TRIM(SUBSTITUTE(AA27,"員工代號:","")),FIND(" ",TRIM(SUBSTITUTE(AA27,"員工代號:","")))+1,255))-2)&RIGHT(MID(TRIM(SUBSTITUTE(AA27,"員工代號:","")),FIND(" ",TRIM(SUBSTITUTE(AA27,"員工代號:","")))+1,255),1)))) | C27: 46191 | D27: 四 | E27: 07:53 | F27: 17:09 | G27: 0.32847222 | H27: 0.71458333 | I27: 0.71458333 | J27: 0.38611111 | K27: 1 | L27: 2026-06 | AA27: 員工代號:97668 郭靖
A28: 27 | B28: =IF(AA28="","",IF(ISNUMBER(SEARCH("員工代號:",AA28)),"員工代號:","")&LEFT(LEFT(TRIM(SUBSTITUTE(AA28,"員工代號:","")),FIND(" ",TRIM(SUBSTITUTE(AA28,"員工代號:","")))-1),2)&REPT("*",MAX(1,LEN(LEFT(TRIM(SUBSTITUTE(AA28,"員工代號:","")),FIND(" ",TRIM(SUBSTITUTE(AA28,"員工代號:","")))-1))-4))&RIGHT(LEFT(TRIM(SUBSTITUTE(AA28,"員工代號:","")),FIND(" ",TRIM(SUBSTITUTE(AA28,"員工代號:","")))-1),2)&" "&IF(LEN(MID(TRIM(SUBSTITUTE(AA28,"員工代號:","")),FIND(" ",TRIM(SUBSTITUTE(AA28,"員工代號:","")))+1,255))<=1,"*",IF(LEN(MID(TRIM(SUBSTITUTE(AA28,"員工代號:","")),FIND(" ",TRIM(SUBSTITUTE(AA28,"員工代號:","")))+1,255))=2,LEFT(MID(TRIM(SUBSTITUTE(AA28,"員工代號:","")),FIND(" ",TRIM(SUBSTITUTE(AA28,"員工代號:","")))+1,255),1)&"*",LEFT(MID(TRIM(SUBSTITUTE(AA28,"員工代號:","")),FIND(" ",TRIM(SUBSTITUTE(AA28,"員工代號:","")))+1,255),1)&REPT("*",LEN(MID(TRIM(SUBSTITUTE(AA28,"員工代號:","")),FIND(" ",TRIM(SUBSTITUTE(AA28,"員工代號:","")))+1,255))-2)&RIGHT(MID(TRIM(SUBSTITUTE(AA28,"員工代號:","")),FIND(" ",TRIM(SUBSTITUTE(AA28,"員工代號:","")))+1,255),1)))) | C28: 46192 | D28: 五 | L28: 2026-06 | AA28: 員工代號:97668 郭靖
A29: 28 | B29: =IF(AA29="","",IF(ISNUMBER(SEARCH("員工代號:",AA29)),"員工代號:","")&LEFT(LEFT(TRIM(SUBSTITUTE(AA29,"員工代號:","")),FIND(" ",TRIM(SUBSTITUTE(AA29,"員工代號:","")))-1),2)&REPT("*",MAX(1,LEN(LEFT(TRIM(SUBSTITUTE(AA29,"員工代號:","")),FIND(" ",TRIM(SUBSTITUTE(AA29,"員工代號:","")))-1))-4))&RIGHT(LEFT(TRIM(SUBSTITUTE(AA29,"員工代號:","")),FIND(" ",TRIM(SUBSTITUTE(AA29,"員工代號:","")))-1),2)&" "&IF(LEN(MID(TRIM(SUBSTITUTE(AA29,"員工代號:","")),FIND(" ",TRIM(SUBSTITUTE(AA29,"員工代號:","")))+1,255))<=1,"*",IF(LEN(MID(TRIM(SUBSTITUTE(AA29,"員工代號:","")),FIND(" ",TRIM(SUBSTITUTE(AA29,"員工代號:","")))+1,255))=2,LEFT(MID(TRIM(SUBSTITUTE(AA29,"員工代號:","")),FIND(" ",TRIM(SUBSTITUTE(AA29,"員工代號:","")))+1,255),1)&"*",LEFT(MID(TRIM(SUBSTITUTE(AA29,"員工代號:","")),FIND(" ",TRIM(SUBSTITUTE(AA29,"員工代號:","")))+1,255),1)&REPT("*",LEN(MID(TRIM(SUBSTITUTE(AA29,"員工代號:","")),FIND(" ",TRIM(SUBSTITUTE(AA29,"員工代號:","")))+1,255))-2)&RIGHT(MID(TRIM(SUBSTITUTE(AA29,"員工代號:","")),FIND(" ",TRIM(SUBSTITUTE(AA29,"員工代號:","")))+1,255),1)))) | C29: 46193 | D29: 六 | L29: 2026-06 | AA29: 員工代號:97668 郭靖
A30: 29 | B30: =IF(AA30="","",IF(ISNUMBER(SEARCH("員工代號:",AA30)),"員工代號:","")&LEFT(LEFT(TRIM(SUBSTITUTE(AA30,"員工代號:","")),FIND(" ",TRIM(SUBSTITUTE(AA30,"員工代號:","")))-1),2)&REPT("*",MAX(1,LEN(LEFT(TRIM(SUBSTITUTE(AA30,"員工代號:","")),FIND(" ",TRIM(SUBSTITUTE(AA30,"員工代號:","")))-1))-4))&RIGHT(LEFT(TRIM(SUBSTITUTE(AA30,"員工代號:","")),FIND(" ",TRIM(SUBSTITUTE(AA30,"員工代號:","")))-1),2)&" "&IF(LEN(MID(TRIM(SUBSTITUTE(AA30,"員工代號:","")),FIND(" ",TRIM(SUBSTITUTE(AA30,"員工代號:","")))+1,255))<=1,"*",IF(LEN(MID(TRIM(SUBSTITUTE(AA30,"員工代號:","")),FIND(" ",TRIM(SUBSTITUTE(AA30,"員工代號:","")))+1,255))=2,LEFT(MID(TRIM(SUBSTITUTE(AA30,"員工代號:","")),FIND(" ",TRIM(SUBSTITUTE(AA30,"員工代號:","")))+1,255),1)&"*",LEFT(MID(TRIM(SUBSTITUTE(AA30,"員工代號:","")),FIND(" ",TRIM(SUBSTITUTE(AA30,"員工代號:","")))+1,255),1)&REPT("*",LEN(MID(TRIM(SUBSTITUTE(AA30,"員工代號:","")),FIND(" ",TRIM(SUBSTITUTE(AA30,"員工代號:","")))+1,255))-2)&RIGHT(MID(TRIM(SUBSTITUTE(AA30,"員工代號:","")),FIND(" ",TRIM(SUBSTITUTE(AA30,"員工代號:","")))+1,255),1)))) | C30: 46194 | D30: 日 | L30: 2026-06 | AA30: 員工代號:97668 郭靖
A31: 30 | B31: =IF(AA31="","",IF(ISNUMBER(SEARCH("員工代號:",AA31)),"員工代號:","")&LEFT(LEFT(TRIM(SUBSTITUTE(AA31,"員工代號:","")),FIND(" ",TRIM(SUBSTITUTE(AA31,"員工代號:","")))-1),2)&REPT("*",MAX(1,LEN(LEFT(TRIM(SUBSTITUTE(AA31,"員工代號:","")),FIND(" ",TRIM(SUBSTITUTE(AA31,"員工代號:","")))-1))-4))&RIGHT(LEFT(TRIM(SUBSTITUTE(AA31,"員工代號:","")),FIND(" ",TRIM(SUBSTITUTE(AA31,"員工代號:","")))-1),2)&" "&IF(LEN(MID(TRIM(SUBSTITUTE(AA31,"員工代號:","")),FIND(" ",TRIM(SUBSTITUTE(AA31,"員工代號:","")))+1,255))<=1,"*",IF(LEN(MID(TRIM(SUBSTITUTE(AA31,"員工代號:","")),FIND(" ",TRIM(SUBSTITUTE(AA31,"員工代號:","")))+1,255))=2,LEFT(MID(TRIM(SUBSTITUTE(AA31,"員工代號:","")),FIND(" ",TRIM(SUBSTITUTE(AA31,"員工代號:","")))+1,255),1)&"*",LEFT(MID(TRIM(SUBSTITUTE(AA31,"員工代號:","")),FIND(" ",TRIM(SUBSTITUTE(AA31,"員工代號:","")))+1,255),1)&REPT("*",LEN(MID(TRIM(SUBSTITUTE(AA31,"員工代號:","")),FIND(" ",TRIM(SUBSTITUTE(AA31,"員工代號:","")))+1,255))-2)&RIGHT(MID(TRIM(SUBSTITUTE(AA31,"員工代號:","")),FIND(" ",TRIM(SUBSTITUTE(AA31,"員工代號:","")))+1,255),1)))) | C31: 46195 | D31: 一 | E31: 07:53 | F31: 19:34 | G31: 0.32847222 | H31: 0.81527778 | I31: 0.8125 | J31: 0.48402778 | K31: 1 | L31: 2026-06 | AA31: 員工代號:97668 郭靖
A32: 31 | B32: =IF(AA32="","",IF(ISNUMBER(SEARCH("員工代號:",AA32)),"員工代號:","")&LEFT(LEFT(TRIM(SUBSTITUTE(AA32,"員工代號:","")),FIND(" ",TRIM(SUBSTITUTE(AA32,"員工代號:","")))-1),2)&REPT("*",MAX(1,LEN(LEFT(TRIM(SUBSTITUTE(AA32,"員工代號:","")),FIND(" ",TRIM(SUBSTITUTE(AA32,"員工代號:","")))-1))-4))&RIGHT(LEFT(TRIM(SUBSTITUTE(AA32,"員工代號:","")),FIND(" ",TRIM(SUBSTITUTE(AA32,"員工代號:","")))-1),2)&" "&IF(LEN(MID(TRIM(SUBSTITUTE(AA32,"員工代號:","")),FIND(" ",TRIM(SUBSTITUTE(AA32,"員工代號:","")))+1,255))<=1,"*",IF(LEN(MID(TRIM(SUBSTITUTE(AA32,"員工代號:","")),FIND(" ",TRIM(SUBSTITUTE(AA32,"員工代號:","")))+1,255))=2,LEFT(MID(TRIM(SUBSTITUTE(AA32,"員工代號:","")),FIND(" ",TRIM(SUBSTITUTE(AA32,"員工代號:","")))+1,255),1)&"*",LEFT(MID(TRIM(SUBSTITUTE(AA32,"員工代號:","")),FIND(" ",TRIM(SUBSTITUTE(AA32,"員工代號:","")))+1,255),1)&REPT("*",LEN(MID(TRIM(SUBSTITUTE(AA32,"員工代號:","")),FIND(" ",TRIM(SUBSTITUTE(AA32,"員工代號:","")))+1,255))-2)&RIGHT(MID(TRIM(SUBSTITUTE(AA32,"員工代號:","")),FIND(" ",TRIM(SUBSTITUTE(AA32,"員工代號:","")))+1,255),1)))) | C32: 46196 | D32: 二 | E32: 07:53 | F32: 19:33 | G32: 0.32847222 | H32: 0.81458333 | I32: 0.8125 | J32: 0.48402778 | K32: 1 | L32: 2026-06 | AA32: 員工代號:97668 郭靖
A33: 32 | B33: =IF(AA33="","",IF(ISNUMBER(SEARCH("員工代號:",AA33)),"員工代號:","")&LEFT(LEFT(TRIM(SUBSTITUTE(AA33,"員工代號:","")),FIND(" ",TRIM(SUBSTITUTE(AA33,"員工代號:","")))-1),2)&REPT("*",MAX(1,LEN(LEFT(TRIM(SUBSTITUTE(AA33,"員工代號:","")),FIND(" ",TRIM(SUBSTITUTE(AA33,"員工代號:","")))-1))-4))&RIGHT(LEFT(TRIM(SUBSTITUTE(AA33,"員工代號:","")),FIND(" ",TRIM(SUBSTITUTE(AA33,"員工代號:","")))-1),2)&" "&IF(LEN(MID(TRIM(SUBSTITUTE(AA33,"員工代號:","")),FIND(" ",TRIM(SUBSTITUTE(AA33,"員工代號:","")))+1,255))<=1,"*",IF(LEN(MID(TRIM(SUBSTITUTE(AA33,"員工代號:","")),FIND(" ",TRIM(SUBSTITUTE(AA33,"員工代號:","")))+1,255))=2,LEFT(MID(TRIM(SUBSTITUTE(AA33,"員工代號:","")),FIND(" ",TRIM(SUBSTITUTE(AA33,"員工代號:","")))+1,255),1)&"*",LEFT(MID(TRIM(SUBSTITUTE(AA33,"員工代號:","")),FIND(" ",TRIM(SUBSTITUTE(AA33,"員工代號:","")))+1,255),1)&REPT("*",LEN(MID(TRIM(SUBSTITUTE(AA33,"員工代號:","")),FIND(" ",TRIM(SUBSTITUTE(AA33,"員工代號:","")))+1,255))-2)&RIGHT(MID(TRIM(SUBSTITUTE(AA33,"員工代號:","")),FIND(" ",TRIM(SUBSTITUTE(AA33,"員工代號:","")))+1,255),1)))) | C33: 46197 | D33: 三 | E33: 07:56 | F33: 17:07 | G33: 0.33055556 | H33: 0.71319444 | I33: 0.71319444 | J33: 0.38263889 | K33: 1 | L33: 2026-06 | AA33: 員工代號:97668 郭靖
A34: 33 | B34: =IF(AA34="","",IF(ISNUMBER(SEARCH("員工代號:",AA34)),"員工代號:","")&LEFT(LEFT(TRIM(SUBSTITUTE(AA34,"員工代號:","")),FIND(" ",TRIM(SUBSTITUTE(AA34,"員工代號:","")))-1),2)&REPT("*",MAX(1,LEN(LEFT(TRIM(SUBSTITUTE(AA34,"員工代號:","")),FIND(" ",TRIM(SUBSTITUTE(AA34,"員工代號:","")))-1))-4))&RIGHT(LEFT(TRIM(SUBSTITUTE(AA34,"員工代號:","")),FIND(" ",TRIM(SUBSTITUTE(AA34,"員工代號:","")))-1),2)&" "&IF(LEN(MID(TRIM(SUBSTITUTE(AA34,"員工代號:","")),FIND(" ",TRIM(SUBSTITUTE(AA34,"員工代號:","")))+1,255))<=1,"*",IF(LEN(MID(TRIM(SUBSTITUTE(AA34,"員工代號:","")),FIND(" ",TRIM(SUBSTITUTE(AA34,"員工代號:","")))+1,255))=2,LEFT(MID(TRIM(SUBSTITUTE(AA34,"員工代號:","")),FIND(" ",TRIM(SUBSTITUTE(AA34,"員工代號:","")))+1,255),1)&"*",LEFT(MID(TRIM(SUBSTITUTE(AA34,"員工代號:","")),FIND(" ",TRIM(SUBSTITUTE(AA34,"員工代號:","")))+1,255),1)&REPT("*",LEN(MID(TRIM(SUBSTITUTE(AA34,"員工代號:","")),FIND(" ",TRIM(SUBSTITUTE(AA34,"員工代號:","")))+1,255))-2)&RIGHT(MID(TRIM(SUBSTITUTE(AA34,"員工代號:","")),FIND(" ",TRIM(SUBSTITUTE(AA34,"員工代號:","")))+1,255),1)))) | C34: 46198 | D34: 四 | E34: 07:55 | F34: 20:36 | G34: 0.32986111 | H34: 0.85833333 | I34: 0.8125 | J34: 0.48263889 | K34: 1 | L34: 2026-06 | AA34: 員工代號:97668 郭靖
A35: 34 | B35: =IF(AA35="","",IF(ISNUMBER(SEARCH("員工代號:",AA35)),"員工代號:","")&LEFT(LEFT(TRIM(SUBSTITUTE(AA35,"員工代號:","")),FIND(" ",TRIM(SUBSTITUTE(AA35,"員工代號:","")))-1),2)&REPT("*",MAX(1,LEN(LEFT(TRIM(SUBSTITUTE(AA35,"員工代號:","")),FIND(" ",TRIM(SUBSTITUTE(AA35,"員工代號:","")))-1))-4))&RIGHT(LEFT(TRIM(SUBSTITUTE(AA35,"員工代號:","")),FIND(" ",TRIM(SUBSTITUTE(AA35,"員工代號:","")))-1),2)&" "&IF(LEN(MID(TRIM(SUBSTITUTE(AA35,"員工代號:","")),FIND(" ",TRIM(SUBSTITUTE(AA35,"員工代號:","")))+1,255))<=1,"*",IF(LEN(MID(TRIM(SUBSTITUTE(AA35,"員工代號:","")),FIND(" ",TRIM(SUBSTITUTE(AA35,"員工代號:","")))+1,255))=2,LEFT(MID(TRIM(SUBSTITUTE(AA35,"員工代號:","")),FIND(" ",TRIM(SUBSTITUTE(AA35,"員工代號:","")))+1,255),1)&"*",LEFT(MID(TRIM(SUBSTITUTE(AA35,"員工代號:","")),FIND(" ",TRIM(SUBSTITUTE(AA35,"員工代號:","")))+1,255),1)&REPT("*",LEN(MID(TRIM(SUBSTITUTE(AA35,"員工代號:","")),FIND(" ",TRIM(SUBSTITUTE(AA35,"員工代號:","")))+1,255))-2)&RIGHT(MID(TRIM(SUBSTITUTE(AA35,"員工代號:","")),FIND(" ",TRIM(SUBSTITUTE(AA35,"員工代號:","")))+1,255),1)))) | C35: 46199 | D35: 五 | E35: 07:55 | F35: 17:07 | G35: 0.32986111 | H35: 0.71319444 | I35: 0.71319444 | J35: 0.38333333 | K35: 1 | L35: 2026-06 | AA35: 員工代號:97668 郭靖
A36: 35 | B36: =IF(AA36="","",IF(ISNUMBER(SEARCH("員工代號:",AA36)),"員工代號:","")&LEFT(LEFT(TRIM(SUBSTITUTE(AA36,"員工代號:","")),FIND(" ",TRIM(SUBSTITUTE(AA36,"員工代號:","")))-1),2)&REPT("*",MAX(1,LEN(LEFT(TRIM(SUBSTITUTE(AA36,"員工代號:","")),FIND(" ",TRIM(SUBSTITUTE(AA36,"員工代號:","")))-1))-4))&RIGHT(LEFT(TRIM(SUBSTITUTE(AA36,"員工代號:","")),FIND(" ",TRIM(SUBSTITUTE(AA36,"員工代號:","")))-1),2)&" "&IF(LEN(MID(TRIM(SUBSTITUTE(AA36,"員工代號:","")),FIND(" ",TRIM(SUBSTITUTE(AA36,"員工代號:","")))+1,255))<=1,"*",IF(LEN(MID(TRIM(SUBSTITUTE(AA36,"員工代號:","")),FIND(" ",TRIM(SUBSTITUTE(AA36,"員工代號:","")))+1,255))=2,LEFT(MID(TRIM(SUBSTITUTE(AA36,"員工代號:","")),FIND(" ",TRIM(SUBSTITUTE(AA36,"員工代號:","")))+1,255),1)&"*",LEFT(MID(TRIM(SUBSTITUTE(AA36,"員工代號:","")),FIND(" ",TRIM(SUBSTITUTE(AA36,"員工代號:","")))+1,255),1)&REPT("*",LEN(MID(TRIM(SUBSTITUTE(AA36,"員工代號:","")),FIND(" ",TRIM(SUBSTITUTE(AA36,"員工代號:","")))+1,255))-2)&RIGHT(MID(TRIM(SUBSTITUTE(AA36,"員工代號:","")),FIND(" ",TRIM(SUBSTITUTE(AA36,"員工代號:","")))+1,255),1)))) | C36: 46200 | D36: 六 | E36: 遲到08:04 | F36: 早退15:08 | G36: 0.33611111 | H36: 0.63055556 | I36: 0.63055556 | L36: 2026-06 | AA36: 員工代號:97668 郭靖
A37: 36 | B37: =IF(AA37="","",IF(ISNUMBER(SEARCH("員工代號:",AA37)),"員工代號:","")&LEFT(LEFT(TRIM(SUBSTITUTE(AA37,"員工代號:","")),FIND(" ",TRIM(SUBSTITUTE(AA37,"員工代號:","")))-1),2)&REPT("*",MAX(1,LEN(LEFT(TRIM(SUBSTITUTE(AA37,"員工代號:","")),FIND(" ",TRIM(SUBSTITUTE(AA37,"員工代號:","")))-1))-4))&RIGHT(LEFT(TRIM(SUBSTITUTE(AA37,"員工代號:","")),FIND(" ",TRIM(SUBSTITUTE(AA37,"員工代號:","")))-1),2)&" "&IF(LEN(MID(TRIM(SUBSTITUTE(AA37,"員工代號:","")),FIND(" ",TRIM(SUBSTITUTE(AA37,"員工代號:","")))+1,255))<=1,"*",IF(LEN(MID(TRIM(SUBSTITUTE(AA37,"員工代號:","")),FIND(" ",TRIM(SUBSTITUTE(AA37,"員工代號:","")))+1,255))=2,LEFT(MID(TRIM(SUBSTITUTE(AA37,"員工代號:","")),FIND(" ",TRIM(SUBSTITUTE(AA37,"員工代號:","")))+1,255),1)&"*",LEFT(MID(TRIM(SUBSTITUTE(AA37,"員工代號:","")),FIND(" ",TRIM(SUBSTITUTE(AA37,"員工代號:","")))+1,255),1)&REPT("*",LEN(MID(TRIM(SUBSTITUTE(AA37,"員工代號:","")),FIND(" ",TRIM(SUBSTITUTE(AA37,"員工代號:","")))+1,255))-2)&RIGHT(MID(TRIM(SUBSTITUTE(AA37,"員工代號:","")),FIND(" ",TRIM(SUBSTITUTE(AA37,"員工代號:","")))+1,255),1)))) | C37: 46201 | D37: 日 | L37: 2026-06 | AA37: 員工代號:97668 郭靖
A38: 37 | B38: =IF(AA38="","",IF(ISNUMBER(SEARCH("員工代號:",AA38)),"員工代號:","")&LEFT(LEFT(TRIM(SUBSTITUTE(AA38,"員工代號:","")),FIND(" ",TRIM(SUBSTITUTE(AA38,"員工代號:","")))-1),2)&REPT("*",MAX(1,LEN(LEFT(TRIM(SUBSTITUTE(AA38,"員工代號:","")),FIND(" ",TRIM(SUBSTITUTE(AA38,"員工代號:","")))-1))-4))&RIGHT(LEFT(TRIM(SUBSTITUTE(AA38,"員工代號:","")),FIND(" ",TRIM(SUBSTITUTE(AA38,"員工代號:","")))-1),2)&" "&IF(LEN(MID(TRIM(SUBSTITUTE(AA38,"員工代號:","")),FIND(" ",TRIM(SUBSTITUTE(AA38,"員工代號:","")))+1,255))<=1,"*",IF(LEN(MID(TRIM(SUBSTITUTE(AA38,"員工代號:","")),FIND(" ",TRIM(SUBSTITUTE(AA38,"員工代號:","")))+1,255))=2,LEFT(MID(TRIM(SUBSTITUTE(AA38,"員工代號:","")),FIND(" ",TRIM(SUBSTITUTE(AA38,"員工代號:","")))+1,255),1)&"*",LEFT(MID(TRIM(SUBSTITUTE(AA38,"員工代號:","")),FIND(" ",TRIM(SUBSTITUTE(AA38,"員工代號:","")))+1,255),1)&REPT("*",LEN(MID(TRIM(SUBSTITUTE(AA38,"員工代號:","")),FIND(" ",TRIM(SUBSTITUTE(AA38,"員工代號:","")))+1,255))-2)&RIGHT(MID(TRIM(SUBSTITUTE(AA38,"員工代號:","")),FIND(" ",TRIM(SUBSTITUTE(AA38,"員工代號:","")))+1,255),1)))) | C38: 46202 | D38: 一 | E38: 遲到08:25 | F38: 17:03 | G38: 0.35069444 | H38: 0.71041667 | I38: 0.71041667 | J38: 0.35972222 | K38: 1 | L38: 2026-06 | AA38: 員工代號:97668 郭靖
A39: 38 | B39: =IF(AA39="","",IF(ISNUMBER(SEARCH("員工代號:",AA39)),"員工代號:","")&LEFT(LEFT(TRIM(SUBSTITUTE(AA39,"員工代號:","")),FIND(" ",TRIM(SUBSTITUTE(AA39,"員工代號:","")))-1),2)&REPT("*",MAX(1,LEN(LEFT(TRIM(SUBSTITUTE(AA39,"員工代號:","")),FIND(" ",TRIM(SUBSTITUTE(AA39,"員工代號:","")))-1))-4))&RIGHT(LEFT(TRIM(SUBSTITUTE(AA39,"員工代號:","")),FIND(" ",TRIM(SUBSTITUTE(AA39,"員工代號:","")))-1),2)&" "&IF(LEN(MID(TRIM(SUBSTITUTE(AA39,"員工代號:","")),FIND(" ",TRIM(SUBSTITUTE(AA39,"員工代號:","")))+1,255))<=1,"*",IF(LEN(MID(TRIM(SUBSTITUTE(AA39,"員工代號:","")),FIND(" ",TRIM(SUBSTITUTE(AA39,"員工代號:","")))+1,255))=2,LEFT(MID(TRIM(SUBSTITUTE(AA39,"員工代號:","")),FIND(" ",TRIM(SUBSTITUTE(AA39,"員工代號:","")))+1,255),1)&"*",LEFT(MID(TRIM(SUBSTITUTE(AA39,"員工代號:","")),FIND(" ",TRIM(SUBSTITUTE(AA39,"員工代號:","")))+1,255),1)&REPT("*",LEN(MID(TRIM(SUBSTITUTE(AA39,"員工代號:","")),FIND(" ",TRIM(SUBSTITUTE(AA39,"員工代號:","")))+1,255))-2)&RIGHT(MID(TRIM(SUBSTITUTE(AA39,"員工代號:","")),FIND(" ",TRIM(SUBSTITUTE(AA39,"員工代號:","")))+1,255),1)))) | C39: 46203 | D39: 二 | E39: 07:55 | F39: 17:08 | G39: 0.32986111 | H39: 0.71388889 | I39: 0.71388889 | J39: 0.38402778 | K39: 1 | L39: 2026-06 | AA39: 員工代號:97668 郭靖
A50: 49 | B50: =IF(AA50="","",IF(ISNUMBER(SEARCH("員工代號:",AA50)),"員工代號:","")&LEFT(LEFT(TRIM(SUBSTITUTE(AA50,"員工代號:","")),FIND(" ",TRIM(SUBSTITUTE(AA50,"員工代號:","")))-1),2)&REPT("*",MAX(1,LEN(LEFT(TRIM(SUBSTITUTE(AA50,"員工代號:","")),FIND(" ",TRIM(SUBSTITUTE(AA50,"員工代號:","")))-1))-4))&RIGHT(LEFT(TRIM(SUBSTITUTE(AA50,"員工代號:","")),FIND(" ",TRIM(SUBSTITUTE(AA50,"員工代號:","")))-1),2)&" "&IF(LEN(MID(TRIM(SUBSTITUTE(AA50,"員工代號:","")),FIND(" ",TRIM(SUBSTITUTE(AA50,"員工代號:","")))+1,255))<=1,"*",IF(LEN(MID(TRIM(SUBSTITUTE(AA50,"員工代號:","")),FIND(" ",TRIM(SUBSTITUTE(AA50,"員工代號:","")))+1,255))=2,LEFT(MID(TRIM(SUBSTITUTE(AA50,"員工代號:","")),FIND(" ",TRIM(SUBSTITUTE(AA50,"員工代號:","")))+1,255),1)&"*",LEFT(MID(TRIM(SUBSTITUTE(AA50,"員工代號:","")),FIND(" ",TRIM(SUBSTITUTE(AA50,"員工代號:","")))+1,255),1)&REPT("*",LEN(MID(TRIM(SUBSTITUTE(AA50,"員工代號:","")),FIND(" ",TRIM(SUBSTITUTE(AA50,"員工代號:","")))+1,255))-2)&RIGHT(MID(TRIM(SUBSTITUTE(AA50,"員工代號:","")),FIND(" ",TRIM(SUBSTITUTE(AA50,"員工代號:","")))+1,255),1)))) | C50: 46174 | D50: 一 | E50: 07:29 | F50: 19:32 | G50: 0.31180556 | H50: 0.81388889 | I50: 0.8125 | J50: 0.50069444 | K50: 1 | L50: 2026-06 | AA50: 員工代號:85479 黃蓉
A51: 50 | B51: =IF(AA51="","",IF(ISNUMBER(SEARCH("員工代號:",AA51)),"員工代號:","")&LEFT(LEFT(TRIM(SUBSTITUTE(AA51,"員工代號:","")),FIND(" ",TRIM(SUBSTITUTE(AA51,"員工代號:","")))-1),2)&REPT("*",MAX(1,LEN(LEFT(TRIM(SUBSTITUTE(AA51,"員工代號:","")),FIND(" ",TRIM(SUBSTITUTE(AA51,"員工代號:","")))-1))-4))&RIGHT(LEFT(TRIM(SUBSTITUTE(AA51,"員工代號:","")),FIND(" ",TRIM(SUBSTITUTE(AA51,"員工代號:","")))-1),2)&" "&IF(LEN(MID(TRIM(SUBSTITUTE(AA51,"員工代號:","")),FIND(" ",TRIM(SUBSTITUTE(AA51,"員工代號:","")))+1,255))<=1,"*",IF(LEN(MID(TRIM(SUBSTITUTE(AA51,"員工代號:","")),FIND(" ",TRIM(SUBSTITUTE(AA51,"員工代號:","")))+1,255))=2,LEFT(MID(TRIM(SUBSTITUTE(AA51,"員工代號:","")),FIND(" ",TRIM(SUBSTITUTE(AA51,"員工代號:","")))+1,255),1)&"*",LEFT(MID(TRIM(SUBSTITUTE(AA51,"員工代號:","")),FIND(" ",TRIM(SUBSTITUTE(AA51,"員工代號:","")))+1,255),1)&REPT("*",LEN(MID(TRIM(SUBSTITUTE(AA51,"員工代號:","")),FIND(" ",TRIM(SUBSTITUTE(AA51,"員工代號:","")))+1,255))-2)&RIGHT(MID(TRIM(SUBSTITUTE(AA51,"員工代號:","")),FIND(" ",TRIM(SUBSTITUTE(AA51,"員工代號:","")))+1,255),1)))) | C51: 46175 | D51: 二 | E51: 07:25 | F51: 20:32 | G51: 0.30902778 | H51: 0.85555556 | I51: 0.8125 | J51: 0.50347222 | K51: 1 | L51: 2026-06 | AA51: 員工代號:85479 黃蓉
A52: 51 | B52: =IF(AA52="","",IF(ISNUMBER(SEARCH("員工代號:",AA52)),"員工代號:","")&LEFT(LEFT(TRIM(SUBSTITUTE(AA52,"員工代號:","")),FIND(" ",TRIM(SUBSTITUTE(AA52,"員工代號:","")))-1),2)&REPT("*",MAX(1,LEN(LEFT(TRIM(SUBSTITUTE(AA52,"員工代號:","")),FIND(" ",TRIM(SUBSTITUTE(AA52,"員工代號:","")))-1))-4))&RIGHT(LEFT(TRIM(SUBSTITUTE(AA52,"員工代號:","")),FIND(" ",TRIM(SUBSTITUTE(AA52,"員工代號:","")))-1),2)&" "&IF(LEN(MID(TRIM(SUBSTITUTE(AA52,"員工代號:","")),FIND(" ",TRIM(SUBSTITUTE(AA52,"員工代號:","")))+1,255))<=1,"*",IF(LEN(MID(TRIM(SUBSTITUTE(AA52,"員工代號:","")),FIND(" ",TRIM(SUBSTITUTE(AA52,"員工代號:","")))+1,255))=2,LEFT(MID(TRIM(SUBSTITUTE(AA52,"員工代號:","")),FIND(" ",TRIM(SUBSTITUTE(AA52,"員工代號:","")))+1,255),1)&"*",LEFT(MID(TRIM(SUBSTITUTE(AA52,"員工代號:","")),FIND(" ",TRIM(SUBSTITUTE(AA52,"員工代號:","")))+1,255),1)&REPT("*",LEN(MID(TRIM(SUBSTITUTE(AA52,"員工代號:","")),FIND(" ",TRIM(SUBSTITUTE(AA52,"員工代號:","")))+1,255))-2)&RIGHT(MID(TRIM(SUBSTITUTE(AA52,"員工代號:","")),FIND(" ",TRIM(SUBSTITUTE(AA52,"員工代號:","")))+1,255),1)))) | C52: 46176 | D52: 三 | E52: 07:29 | F52: 19:32 | G52: 0.31180556 | H52: 0.81388889 | I52: 0.8125 | J52: 0.50069444 | K52: 1 | L52: 2026-06 | AA52: 員工代號:85479 黃蓉
A53: 52 | B53: =IF(AA53="","",IF(ISNUMBER(SEARCH("員工代號:",AA53)),"員工代號:","")&LEFT(LEFT(TRIM(SUBSTITUTE(AA53,"員工代號:","")),FIND(" ",TRIM(SUBSTITUTE(AA53,"員工代號:","")))-1),2)&REPT("*",MAX(1,LEN(LEFT(TRIM(SUBSTITUTE(AA53,"員工代號:","")),FIND(" ",TRIM(SUBSTITUTE(AA53,"員工代號:","")))-1))-4))&RIGHT(LEFT(TRIM(SUBSTITUTE(AA53,"員工代號:","")),FIND(" ",TRIM(SUBSTITUTE(AA53,"員工代號:","")))-1),2)&" "&IF(LEN(MID(TRIM(SUBSTITUTE(AA53,"員工代號:","")),FIND(" ",TRIM(SUBSTITUTE(AA53,"員工代號:","")))+1,255))<=1,"*",IF(LEN(MID(TRIM(SUBSTITUTE(AA53,"員工代號:","")),FIND(" ",TRIM(SUBSTITUTE(AA53,"員工代號:","")))+1,255))=2,LEFT(MID(TRIM(SUBSTITUTE(AA53,"員工代號:","")),FIND(" ",TRIM(SUBSTITUTE(AA53,"員工代號:","")))+1,255),1)&"*",LEFT(MID(TRIM(SUBSTITUTE(AA53,"員工代號:","")),FIND(" ",TRIM(SUBSTITUTE(AA53,"員工代號:","")))+1,255),1)&REPT("*",LEN(MID(TRIM(SUBSTITUTE(AA53,"員工代號:","")),FIND(" ",TRIM(SUBSTITUTE(AA53,"員工代號:","")))+1,255))-2)&RIGHT(MID(TRIM(SUBSTITUTE(AA53,"員工代號:","")),FIND(" ",TRIM(SUBSTITUTE(AA53,"員工代號:","")))+1,255),1)))) | C53: 46177 | D53: 四 | E53: 07:25 | F53: 20:32 | G53: 0.30902778 | H53: 0.85555556 | I53: 0.8125 | J53: 0.50347222 | K53: 1 | L53: 2026-06 | AA53: 員工代號:85479 黃蓉
A54: 53 | B54: =IF(AA54="","",IF(ISNUMBER(SEARCH("員工代號:",AA54)),"員工代號:","")&LEFT(LEFT(TRIM(SUBSTITUTE(AA54,"員工代號:","")),FIND(" ",TRIM(SUBSTITUTE(AA54,"員工代號:","")))-1),2)&REPT("*",MAX(1,LEN(LEFT(TRIM(SUBSTITUTE(AA54,"員工代號:","")),FIND(" ",TRIM(SUBSTITUTE(AA54,"員工代號:","")))-1))-4))&RIGHT(LEFT(TRIM(SUBSTITUTE(AA54,"員工代號:","")),FIND(" ",TRIM(SUBSTITUTE(AA54,"員工代號:","")))-1),2)&" "&IF(LEN(MID(TRIM(SUBSTITUTE(AA54,"員工代號:","")),FIND(" ",TRIM(SUBSTITUTE(AA54,"員工代號:","")))+1,255))<=1,"*",IF(LEN(MID(TRIM(SUBSTITUTE(AA54,"員工代號:","")),FIND(" ",TRIM(SUBSTITUTE(AA54,"員工代號:","")))+1,255))=2,LEFT(MID(TRIM(SUBSTITUTE(AA54,"員工代號:","")),FIND(" ",TRIM(SUBSTITUTE(AA54,"員工代號:","")))+1,255),1)&"*",LEFT(MID(TRIM(SUBSTITUTE(AA54,"員工代號:","")),FIND(" ",TRIM(SUBSTITUTE(AA54,"員工代號:","")))+1,255),1)&REPT("*",LEN(MID(TRIM(SUBSTITUTE(AA54,"員工代號:","")),FIND(" ",TRIM(SUBSTITUTE(AA54,"員工代號:","")))+1,255))-2)&RIGHT(MID(TRIM(SUBSTITUTE(AA54,"員工代號:","")),FIND(" ",TRIM(SUBSTITUTE(AA54,"員工代號:","")))+1,255),1)))) | C54: 46178 | D54: 五 | E54: 07:32 | F54: 20:32 | G54: 0.31388889 | H54: 0.85555556 | I54: 0.8125 | J54: 0.49861111 | K54: 1 | L54: 2026-06 | AA54: 員工代號:85479 黃蓉
A55: 54 | B55: =IF(AA55="","",IF(ISNUMBER(SEARCH("員工代號:",AA55)),"員工代號:","")&LEFT(LEFT(TRIM(SUBSTITUTE(AA55,"員工代號:","")),FIND(" ",TRIM(SUBSTITUTE(AA55,"員工代號:","")))-1),2)&REPT("*",MAX(1,LEN(LEFT(TRIM(SUBSTITUTE(AA55,"員工代號:","")),FIND(" ",TRIM(SUBSTITUTE(AA55,"員工代號:","")))-1))-4))&RIGHT(LEFT(TRIM(SUBSTITUTE(AA55,"員工代號:","")),FIND(" ",TRIM(SUBSTITUTE(AA55,"員工代號:","")))-1),2)&" "&IF(LEN(MID(TRIM(SUBSTITUTE(AA55,"員工代號:","")),FIND(" ",TRIM(SUBSTITUTE(AA55,"員工代號:","")))+1,255))<=1,"*",IF(LEN(MID(TRIM(SUBSTITUTE(AA55,"員工代號:","")),FIND(" ",TRIM(SUBSTITUTE(AA55,"員工代號:","")))+1,255))=2,LEFT(MID(TRIM(SUBSTITUTE(AA55,"員工代號:","")),FIND(" ",TRIM(SUBSTITUTE(AA55,"員工代號:","")))+1,255),1)&"*",LEFT(MID(TRIM(SUBSTITUTE(AA55,"員工代號:","")),FIND(" ",TRIM(SUBSTITUTE(AA55,"員工代號:","")))+1,255),1)&REPT("*",LEN(MID(TRIM(SUBSTITUTE(AA55,"員工代號:","")),FIND(" ",TRIM(SUBSTITUTE(AA55,"員工代號:","")))+1,255))-2)&RIGHT(MID(TRIM(SUBSTITUTE(AA55,"員工代號:","")),FIND(" ",TRIM(SUBSTITUTE(AA55,"員工代號:","")))+1,255),1)))) | C55: 46179 | D55: 六 | L55: 2026-06 | AA55: 員工代號:85479 黃蓉
A56: 55 | B56: =IF(AA56="","",IF(ISNUMBER(SEARCH("員工代號:",AA56)),"員工代號:","")&LEFT(LEFT(TRIM(SUBSTITUTE(AA56,"員工代號:","")),FIND(" ",TRIM(SUBSTITUTE(AA56,"員工代號:","")))-1),2)&REPT("*",MAX(1,LEN(LEFT(TRIM(SUBSTITUTE(AA56,"員工代號:","")),FIND(" ",TRIM(SUBSTITUTE(AA56,"員工代號:","")))-1))-4))&RIGHT(LEFT(TRIM(SUBSTITUTE(AA56,"員工代號:","")),FIND(" ",TRIM(SUBSTITUTE(AA56,"員工代號:","")))-1),2)&" "&IF(LEN(MID(TRIM(SUBSTITUTE(AA56,"員工代號:","")),FIND(" ",TRIM(SUBSTITUTE(AA56,"員工代號:","")))+1,255))<=1,"*",IF(LEN(MID(TRIM(SUBSTITUTE(AA56,"員工代號:","")),FIND(" ",TRIM(SUBSTITUTE(AA56,"員工代號:","")))+1,255))=2,LEFT(MID(TRIM(SUBSTITUTE(AA56,"員工代號:","")),FIND(" ",TRIM(SUBSTITUTE(AA56,"員工代號:","")))+1,255),1)&"*",LEFT(MID(TRIM(SUBSTITUTE(AA56,"員工代號:","")),FIND(" ",TRIM(SUBSTITUTE(AA56,"員工代號:","")))+1,255),1)&REPT("*",LEN(MID(TRIM(SUBSTITUTE(AA56,"員工代號:","")),FIND(" ",TRIM(SUBSTITUTE(AA56,"員工代號:","")))+1,255))-2)&RIGHT(MID(TRIM(SUBSTITUTE(AA56,"員工代號:","")),FIND(" ",TRIM(SUBSTITUTE(AA56,"員工代號:","")))+1,255),1)))) | C56: 46180 | D56: 日 | L56: 2026-06 | AA56: 員工代號:85479 黃蓉
...
